Workbook

Sheet COVER
A2: THE KRAFT HEINZ COMPANY (KHC)
A3: Financial Modeling | B3: FY2023A – FY2030E
A4: Data Source | B4: 10-K 2/12/2026
A5: Ticker | B5: NASDAQ: KHC
A6: Currency | B6: USD (millions), unless otherwise stated
A7: Made by | B7: Gonzalo Dalmasso Müller
A10: COLOR CODING
A11: Blue text | B11: Hardcoded inputs / assumptions
A12: Black text | B12: Formulas / calculations
A13: Green text | B13: Cross-sheet links
A16: MODEL STRUCTURE
A17: INPUTS | B17: Historical financials from 10-K + projection assumptions
A18: REVENUE | B18: Revenue buildup by segment — growth rate driver
A19: COGS_OPEX | B19: COGS (% of sales) and OpEx (growth driver) buildups
A20: NWC | B20: Net Working Capital — DSO, DIO, DPO methodology
A21: CAPEX_DA | B21: Capital expenditures and D&A — % of sales
A22: DEBT | B22: Debt schedule — opening balance, draws, repayments, interest
A23: PL | B23: Projected Income Statement (P&L)
A24: BS | B24: Projected Balance Sheet
A25: CF | B25: Projected Cash Flow Statement

Sheet INPUTS
B1: INPUTS — Historical Data (10-K FY2025) & Projection Assumptions
C2: FY2023 | D2: FY2024 | E2: FY2025 | F2: FY2026E | G2: FY2027E | H2: FY2028E | I2: FY2029E | J2: FY2030E
B3: A. INCOME STATEMENT
B4: Net Sales | C4: 26640 | D4: 25846 | E4: 24942
B5: Cost of Products Sold | C5: 17714 | D5: 16878 | E5: 16633
B6: Gross Profit | C6: =C4-C5 -> 8926 | D6: =D4-D5 -> 8968 | E6: =E4-E5 -> 8309
B8: SG&A (excl. impairment losses) | C8: 3692 | D8: 3616 | E8: 3672
B9: D&A (within SG&A/COGS) | C9: 961 | D9: 948 | E9: 968
B10: Goodwill Impairment | C10: 510 | D10: 1638 | E10: 6734
B11: Intangible Impairment | C11: 152 | D11: 2031 | E11: 2572
B12: Operating Income/(Loss) - EBIT | C12: =C6-C8-C10-C11 -> 4572 | D12: =D6-D8-D10-D11 -> 1683 | E12: =E6-E8-E10-E11 -> -4669
B14: Interest Expense | C14: 912 | D14: 912 | E14: 947
B15: Other Expense/(Income) | C15: 27 | D15: -85 | E15: -171
B16: Income/(Loss) Before Tax - EBT | C16: =C12-C14-C15 -> 3633 | D16: =D12-D14-D15 -> 856 | E16: =E12-E14-E15 -> -5445
B18: Tax Provision/(Benefit) | C18: 787 | D18: -1890 | E18: 403
B19: Net Income/(Loss) | C19: =C16-C18 -> 2846 | D19: =D16-D18 -> 2746 | E19: =E16-E18 -> -5848
B21: B. BALANCE SHEET — Historical
B22: ASSETS
B23: Cash & Cash Equivalents | C23: 1400 | D23: 1334 | E23: 2615
B24: Trade Receivables (net) | C24: 2112 | D24: 2147 | E24: 2254
B25: Inventories | C25: 3614 | D25: 3376 | E25: 3167
B26: Other Current Assets | C26: 1803 | D26: 1396 | E26: 2091
B27: Total Current Assets | C27: =SUM(C23:C26) -> 8929 | D27: =SUM(D23:D26) -> 8253 | E27: =SUM(E23:E26) -> 10127
B29: PP&E, net | C29: 7400 | D29: 7152 | E29: 7318
B30: Goodwill | C30: 30600 | D30: 28673 | E30: 22179
B31: Intangible Assets, net | C31: 42000 | D31: 40099 | E31: 37529
B32: Other Non-Current Assets | C32: 4800 | D32: 4708 | E32: 4633
B33: TOTAL ASSETS | C33: =C27+C29+C30+C31+C32 -> 93729 | D33: =D27+D29+D30+D31+D32 -> 88885 | E33: =E27+E29+E30+E31+E32 -> 81786
B35: LIABILITIES AND EQUITY
B36: Accounts Payable | C36: 4496 | D36: 4188 | E36: 4308
B37: Current Portion LT Debt | C37: 652 | D37: 654 | E37: 1908
B38: Other Current Liabilities | C38: 2554 | D38: 2411 | E38: 2562
B39: Total Current Liabilities | C39: =C36+C37+C38 -> 7702 | D39: =D36+D37+D38 -> 7253 | E39: =E36+E37+E38 -> 8778
B41: Long-Term Debt | C41: 19900 | D41: 19215 | E41: 19311
B42: Other Non-Current Liabilities | C42: 11700 | D42: 12494 | E42: 11908
B43: TOTAL LIABILITIES | C43: =C39+C41+C42 -> 39302 | D43: =D39+D41+D42 -> 38962 | E43: =E39+E41+E42 -> 39997
B45: Total Equity | C45: 49688 | D45: 49319 | E45: 41777
B46: TOTAL LIABILITIES & EQUITY | C46: =C43+C45 -> 88990 | D46: =D43+D45 -> 88281 | E46: =E43+E45 -> 81774
B48: C. CASH FLOW — Historical
B49: Net Income/(Loss) | C49: 2846 | D49: 2746 | E49: -5848
...

Sheet REVENUE
A1: REVENUE BUILDUP — By Segment
B2: Driver | C2: FY2023 | D2: FY2024 | E2: FY2025 | F2: FY2026E | G2: FY2027E | H2: FY2028E | I2: FY2029E | J2: FY2030E
A3: North America | B3: YoY Growth | C3: 20126 | D3: 19543 | E3: 18586 | F3: =E3*(1+INPUTS!F72) -> 18028.42 | G3: =F3*(1+INPUTS!G72) -> 17667.852 | H3: =G3*(1+INPUTS!H72) -> 17667.852 | I3: =H3*(1+INPUTS!I72) -> 17844.53 | J3: =I3*(1+INPUTS!J72) -> 18112.198
A4: YoY Growth % | D4: =D3/C3-1 -> -0.028967505 | E4: =E3/D3-1 -> -0.04896894 | F4: =F3/E3-1 -> -0.03 | G4: =G3/F3-1 -> -0.02 | H4: =H3/G3-1 -> 0 | I4: =I3/H3-1 -> 0.01 | J4: =J3/I3-1 -> 0.015
A6: International Dev. Mkts | B6: YoY Growth | C6: 3623 | D6: 3535 | E6: 3539 | F6: =E6*(1+INPUTS!F73) -> 3542.539 | G6: =F6*(1+INPUTS!G73) -> 3560.2517 | H6: =G6*(1+INPUTS!H73) -> 3595.8542 | I6: =H6*(1+INPUTS!I73) -> 3631.8128 | J6: =I6*(1+INPUTS!J73) -> 3686.2899
A7: YoY Growth % | D7: =D6/C6-1 -> -0.024289263 | E7: =E6/D6-1 -> 0.0011315417 | F7: =F6/E6-1 -> 0.001 | G7: =G6/F6-1 -> 0.005 | H7: =H6/G6-1 -> 0.01 | I7: =I6/H6-1 -> 0.01 | J7: =J6/I6-1 -> 0.015
A9: Emerging Markets | B9: YoY Growth | C9: 2891 | D9: 2768 | E9: 2817 | F9: =E9*(1+INPUTS!F74) -> 2867.706 | G9: =F9*(1+INPUTS!G74) -> 2925.0601 | H9: =G9*(1+INPUTS!H74) -> 2983.5613 | I9: =H9*(1+INPUTS!I74) -> 3058.1504 | J9: =I9*(1+INPUTS!J74) -> 3134.6041
A10: YoY Growth % | D10: =D9/C9-1 -> -0.042545832 | E10: =E9/D9-1 -> 0.017702312 | F10: =F9/E9-1 -> 0.018 | G10: =G9/F9-1 -> 0.02 | H10: =H9/G9-1 -> 0.02 | I10: =I9/H9-1 -> 0.025 | J10: =J9/I9-1 -> 0.025
A12: TOTAL NET SALES | B12: Sum of segments | C12: =C3+C6+C9 -> 26640 | D12: =D3+D6+D9 -> 25846 | E12: =E3+E6+E9 -> 24942 | F12: =F3+F6+F9 -> 24438.665 | G12: =G3+G6+G9 -> 24153.163 | H12: =H3+H6+H9 -> 24247.267 | I12: =I3+I6+I9 -> 24534.493 | J12: =J3+J6+J9 -> 24933.092
A13: Total Revenue YoY Growth % | D13: =D12/C12-1 -> -0.029804805 | E13: =E12/D12-1 -> -0.034976399 | F13: =F12/E12-1 -> -0.020180218 | G13: =G12/F12-1 -> -0.011682372 | H13: =H12/G12-1 -> 0.003896124 | I13: =I12/H12-1 -> 0.01184571 | J13: =J12/I12-1 -> 0.01624647

Sheet COGS_OPEX
A1: COGS & OPEX BUILDUP
C2: FY2023 | D2: FY2024 | E2: FY2025 | F2: FY2026E | G2: FY2027E | H2: FY2028E | I2: FY2029E | J2: FY2030E
A3: Net Sales ($mm) | C3: =REVENUE!C12 -> 26640 | D3: =REVENUE!D12 -> 25846 | E3: =REVENUE!E12 -> 24942 | F3: =REVENUE!F12 -> 24438.665 | G3: =REVENUE!G12 -> 24153.163 | H3: =REVENUE!H12 -> 24247.267 | I3: =REVENUE!I12 -> 24534.493 | J3: =REVENUE!J12 -> 24933.092
A5: A. COST OF GOODS SOLD
A6: COGS as % of Net Sales | B6: Assumption | C6: 0.66493994 | D6: 0.65302174 | E6: 0.66686713 | F6: =INPUTS!F76 -> 0.667 | G6: =INPUTS!G76 -> 0.665 | H6: =INPUTS!H76 -> 0.66 | I6: =INPUTS!I76 -> 0.658 | J6: =INPUTS!J76 -> 0.655
A7: Cost of Products Sold ($mm) | B7: Sales × COGS% | C7: =C3*C6 -> 17714 | D7: =D3*D6 -> 16878 | E7: =E3*E6 -> 16633 | F7: =F3*F6 -> 16300.59 | G7: =G3*G6 -> 16061.854 | H7: =H3*H6 -> 16003.196 | I7: =I3*I6 -> 16143.697 | J7: =J3*J6 -> 16331.175
A9: Gross Profit ($mm) | C9: =C3-C7 -> 8926 | D9: =D3-D7 -> 8968 | E9: =E3-E7 -> 8309 | F9: =F3-F7 -> 8138.0754 | G9: =G3-G7 -> 8091.3097 | H9: =H3-H7 -> 8244.0708 | I9: =I3-I7 -> 8390.7967 | J9: =J3-J7 -> 8601.9168
A10: Gross Margin % | C10: =IFERROR(C9/C3,0) -> 0.33506006 | D10: =IFERROR(D9/D3,0) -> 0.34697826 | E10: =IFERROR(E9/E3,0) -> 0.33313287 | F10: =IFERROR(F9/F3,0) -> 0.333 | G10: =IFERROR(G9/G3,0) -> 0.335 | H10: =IFERROR(H9/H3,0) -> 0.34 | I10: =IFERROR(I9/I3,0) -> 0.342 | J10: =IFERROR(J9/J3,0) -> 0.345
A12: B. OPERATING EXPENSES (excl. impairment)
A13: SG&A as % of Net Sales | B13: Assumption | C13: 0.13858859 | D13: 0.13990559 | E13: 0.14722155 | F13: =INPUTS!F77 -> 0.147 | G13: =INPUTS!G77 -> 0.145 | H13: =INPUTS!H77 -> 0.143 | I13: =INPUTS!I77 -> 0.142 | J13: =INPUTS!J77 -> 0.14
A14: SG&A Expenses ($mm) | C14: =C3*C13 -> 3692 | D14: =D3*D13 -> 3616 | E14: =E3*E13 -> 3672 | F14: =F3*F13 -> 3592.4838 | G14: =G3*G13 -> 3502.2087 | H14: =H3*H13 -> 3467.3592 | I14: =I3*I13 -> 3483.898 | J14: =J3*J13 -> 3490.6329
A15: Goodwill Impairment ($mm) | C15: 510 | D15: 1638 | E15: 6734 | F15: =INPUTS!F78 -> 0 | G15: =INPUTS!G78 -> 0 | H15: =INPUTS!H78 -> 0 | I15: =INPUTS!I78 -> 0 | J15: =INPUTS!J78 -> 0
A16: Intangible Impairment ($mm) | C16: 152 | D16: 2031 | E16: 2572 | F16: =INPUTS!F79 -> 0 | G16: =INPUTS!G79 -> 0 | H16: =INPUTS!H79 -> 0 | I16: =INPUTS!I79 -> 0 | J16: =INPUTS!J79 -> 0
A17: Total SG&A (incl. impairment) ($mm) | C17: =C14+C15+C16 -> 4354 | D17: =D14+D15+D16 -> 7285 | E17: =E14+E15+E16 -> 12978 | F17: =COGS_OPEX!F14+COGS_OPEX!F15+COGS_OPEX!F16 -> 3592.4838 | G17: =COGS_OPEX!G14+COGS_OPEX!G15+COGS_OPEX!G16 -> 3502.2087 | H17: =COGS_OPEX!H14+COGS_OPEX!H15+COGS_OPEX!H16 -> 3467.3592 | I17: =COGS_OPEX!I14+COGS_OPEX!I15+COGS_OPEX!I16 -> 3483.898 | J17: =COGS_OPEX!J14+COGS_OPEX!J15+COGS_OPEX!J16 -> 3490.6329
A19: C. EBITDA SUMMARY
A20: Operating Income/(Loss) ($mm) | C20: =C9-C17 -> 4572 | D20: =D9-D17 -> 1683 | E20: =E9-E17 -> -4669 | F20: =COGS_OPEX!F9-COGS_OPEX!F17 -> 4545.5917 | G20: =COGS_OPEX!G9-COGS_OPEX!G17 -> 4589.101 | H20: =COGS_OPEX!H9-COGS_OPEX!H17 -> 4776.7116 | I20: =COGS_OPEX!I9-COGS_OPEX!I17 -> 4906.8986 | J20: =COGS_OPEX!J9-COGS_OPEX!J17 -> 5111.2839
A21: Operating Margin % | C21: =IFERROR(C20/C3,0) -> 0.17162162 | D21: =IFERROR(D20/D3,0) -> 0.065116459 | E21: =IFERROR(E20/E3,0) -> -0.18719429 | F21: =IFERROR(F20/F3,0) -> 0.186 | G21: =IFERROR(G20/G3,0) -> 0.19 | H21: =IFERROR(H20/H3,0) -> 0.197 | I21: =IFERROR(I20/I3,0) -> 0.2 | J21: =IFERROR(J20/J3,0) -> 0.205

Sheet NWC
A1: NET WORKING CAPITAL (NWC) — DSO / DIO / DPO Methodology
A2: DSO = AR/Sales×365 | DIO = Inventory/COGS×365 | DPO = AP/COGS×365 | NWC = AR + Inventory - AP
C3: FY2023 | D3: FY2024 | E3: FY2025 | F3: FY2026E | G3: FY2027E | H3: FY2028E | I3: FY2029E | J3: FY2030E
A4: Net Sales ($mm) | B4: ← REVENUE | C4: =REVENUE!C12 -> 26640 | D4: =REVENUE!D12 -> 25846 | E4: =REVENUE!E12 -> 24942 | F4: =REVENUE!F12 -> 24438.665 | G4: =REVENUE!G12 -> 24153.163 | H4: =REVENUE!H12 -> 24247.267 | I4: =REVENUE!I12 -> 24534.493 | J4: =REVENUE!J12 -> 24933.092
A5: COGS ($mm) | B5: ← COGS_OPEX | C5: =COGS_OPEX!C7 -> 17714 | D5: =COGS_OPEX!D7 -> 16878 | E5: =COGS_OPEX!E7 -> 16633 | F5: =COGS_OPEX!F7 -> 16300.59 | G5: =COGS_OPEX!G7 -> 16061.854 | H5: =COGS_OPEX!H7 -> 16003.196 | I5: =COGS_OPEX!I7 -> 16143.697 | J5: =COGS_OPEX!J7 -> 16331.175
A7: DAYS ASSUMPTIONS
A8: DSO (days) | B8: Calculated / Assumed | C8: 30.3 | D8: 30.3 | E8: 33 | F8: =INPUTS!F82 -> 30 | G8: =INPUTS!G82 -> 30 | H8: =INPUTS!H82 -> 30 | I8: =INPUTS!I82 -> 30 | J8: =INPUTS!J82 -> 30
A9: DIO (days) | B9: Calculated / Assumed | C9: 74.5 | D9: 73 | E9: 69.5 | F9: =INPUTS!F83 -> 69 | G9: =INPUTS!G83 -> 68 | H9: =INPUTS!H83 -> 67 | I9: =INPUTS!I83 -> 66 | J9: =INPUTS!J83 -> 65
A10: DPO (days) | B10: Calculated / Assumed | C10: 92.7 | D10: 90.5 | E10: 94.6 | F10: =INPUTS!F84 -> 95 | G10: =INPUTS!G84 -> 95 | H10: =INPUTS!H84 -> 95 | I10: =INPUTS!I84 -> 95 | J10: =INPUTS!J84 -> 95
A12: BALANCE SHEET ITEMS ($mm)
A13: Accounts Receivable | B13: DSO/365 × Sales | C13: 2112 | D13: 2147 | E13: 2254 | F13: =F8/365*F4 -> 2008.6574 | G13: =G8/365*G4 -> 1985.1915 | H13: =H8/365*H4 -> 1992.9261 | I13: =I8/365*I4 -> 2016.5337 | J13: =J8/365*J4 -> 2049.2952
A14: Inventories | B14: DIO/365 × COGS | C14: 3614 | D14: 3376 | E14: 3167 | F14: =F9/365*F5 -> 3081.4813 | G14: =G9/365*G5 -> 2992.3453 | H14: =H9/365*H5 -> 2937.573 | I14: =I9/365*I5 -> 2919.1342 | J14: =J9/365*J5 -> 2908.2915
A15: Accounts Payable | B15: DPO/365 × COGS | C15: 4496 | D15: 4188 | E15: 4308 | F15: =F10/365*F5 -> 4242.6192 | G15: =G10/365*G5 -> 4180.4825 | H15: =H10/365*H5 -> 4165.2155 | I15: =I10/365*I5 -> 4201.784 | J15: =J10/365*J5 -> 4250.5799
A16: NET WORKING CAPITAL (AR + Inv - AP) | C16: =C13+C14-C15 -> 1230 | D16: =D13+D14-D15 -> 1335 | E16: =E13+E14-E15 -> 1113 | F16: =F13+F14-F15 -> 847.51951 | G16: =G13+G14-G15 -> 797.05439 | H16: =H13+H14-H15 -> 765.28361 | I16: =I13+I14-I15 -> 733.88383 | J16: =J13+J14-J15 -> 707.00686
A17: Change in NWC (increase = cash use) | D17: =D16-C16 -> 105 | E17: =E16-D16 -> -222 | F17: =F16-E16 -> -265.48049 | G17: =G16-F16 -> -50.465118 | H17: =H16-G16 -> -31.770783 | I17: =I16-H16 -> -31.399782 | J17: =J16-I16 -> -26.876969

Sheet CAPEX_DA
A1: CAPEX & DEPRECIATION — % of Net Sales
C2: FY2023 | D2: FY2024 | E2: FY2025 | F2: FY2026E | G2: FY2027E | H2: FY2028E | I2: FY2029E | J2: FY2030E
A3: Net Sales ($mm) | C3: =REVENUE!C12 -> 26640 | D3: =REVENUE!D12 -> 25846 | E3: =REVENUE!E12 -> 24942 | F3: =REVENUE!F12 -> 24438.665 | G3: =REVENUE!G12 -> 24153.163 | H3: =REVENUE!H12 -> 24247.267 | I3: =REVENUE!I12 -> 24534.493 | J3: =REVENUE!J12 -> 24933.092
A5: A. CAPITAL EXPENDITURES
A6: CapEx as % of Net Sales | C6: 0.038025526 | D6: 0.039619283 | E6: 0.032114506 | F6: =INPUTS!F86 -> 0.033 | G6: =INPUTS!G86 -> 0.035 | H6: =INPUTS!H86 -> 0.035 | I6: =INPUTS!I86 -> 0.035 | J6: =INPUTS!J86 -> 0.035
A7: Capital Expenditures ($mm) | C7: =-C3*C6 -> -1013 | D7: =-D3*D6 -> -1024 | E7: =-E3*E6 -> -801 | F7: =-F3*F6 -> -806.47595 | G7: =-G3*G6 -> -845.36072 | H7: =-H3*H6 -> -848.65435 | I7: =-I3*I6 -> -858.70726 | J7: =-J3*J6 -> -872.65822
A9: B. DEPRECIATION & AMORTIZATION
A10: D&A as % of Net Sales | C10: 0.036073574 | D10: 0.03667879 | E10: 0.038810039 | F10: =INPUTS!F75 -> 0 | G10: =INPUTS!G75 -> 0 | H10: =INPUTS!H75 -> 0 | I10: =INPUTS!I75 -> 0 | J10: =INPUTS!J75 -> 0
A11: Depreciation & Amortization ($mm) | C11: =C3*C10 -> 961 | D11: =D3*D10 -> 948 | E11: =E3*E10 -> 968 | F11: =F3*F10 -> 0 | G11: =G3*G10 -> 0 | H11: =H3*H10 -> 0 | I11: =I3*I10 -> 0 | J11: =J3*J10 -> 0
A13: C. PP&E ROLL-FORWARD
A14: PP&E, net — Beginning of Period | C14: N/A | D14: 7400 | E14: 7152 | F14: =E17 -> 7318 | G14: =F17 -> 8124.4759 | H14: =G17 -> 8969.8367 | I14: =H17 -> 9818.491 | J14: =I17 -> 10677.198
A15: + Capital Expenditures | C15: N/A | D15: =-D7 -> 1024 | E15: =-E7 -> 801 | F15: =-F7 -> 806.47595 | G15: =-G7 -> 845.36072 | H15: =-H7 -> 848.65435 | I15: =-I7 -> 858.70726 | J15: =-J7 -> 872.65822
A16: - Depreciation & Amortization | C16: N/A | D16: =-D11 -> -948 | E16: =-E11 -> -968 | F16: =-F11 -> 0 | G16: =-G11 -> 0 | H16: =-H11 -> 0 | I16: =-I11 -> 0 | J16: =-J11 -> 0
A17: PP&E, net — End of Period | C17: 7400 | D17: 7152 | E17: 7318 | F17: =F14+F15+F16 -> 8124.4759 | G17: =G14+G15+G16 -> 8969.8367 | H17: =H14+H15+H16 -> 9818.491 | I17: =I14+I15+I16 -> 10677.198 | J17: =J14+J15+J16 -> 11549.857

Sheet DEBT
A1: DEBT SCHEDULE
C2: FY2023 | D2: FY2024 | E2: FY2025 | F2: FY2026E | G2: FY2027E | H2: FY2028E | I2: FY2029E | J2: FY2030E
A3: TOTAL DEBT (Current + Long-Term)
A4: Debt — Beginning of Period | C4: N/A | D4: 20552 | E4: 19869 | F4: =E7 -> 21219 | G4: =F7 -> 20619 | H4: =G7 -> 20019 | I4: =H7 -> 19419 | J4: =I7 -> 18819
A5: + New Debt Issuance ($mm) | C5: 657 | D5: 594 | E5: 1620 | F5: 0 | G5: 0 | H5: 0 | I5: 0 | J5: 0
A6: - Debt Repayment ($mm) | C6: -848 | D6: -618 | E6: -678 | F6: =-INPUTS!F90 -> -600 | G6: =-INPUTS!G90 -> -600 | H6: =-INPUTS!H90 -> -600 | I6: =-INPUTS!I90 -> -600 | J6: =-INPUTS!J90 -> -600
A7: Debt — End of Period ($mm) | C7: 20552 | D7: 19869 | E7: 21219 | F7: =F4+F5+F6 -> 20619 | G7: =G4+G5+G6 -> 20019 | H7: =H4+H5+H6 -> 19419 | I7: =I4+I5+I6 -> 18819 | J7: =J4+J5+J6 -> 18219
A8: Interest Expense ($mm) | C8: 912 | D8: 912 | E8: 947 | F8: =((((F4+F7)/2)*INPUTS!F89)) -> 878.598 | G8: =((((G4+G7)/2)*INPUTS!G89)) -> 853.398 | H8: =((((H4+H7)/2)*INPUTS!H89)) -> 828.198 | I8: =((((I4+I7)/2)*INPUTS!I89)) -> 802.998 | J8: =((((J4+J7)/2)*INPUTS!J89)) -> 777.798
A9: Implied Interest Rate | C9: N/A | D9: =IFERROR(D8/((D4+D7)/2),0) -> 0.045125059 | E9: =IFERROR(E8/((E4+E7)/2),0) -> 0.046096184 | F9: =IFERROR(F8/((F4+F7)/2),0) -> 0.042 | G9: =IFERROR(G8/((G4+G7)/2),0) -> 0.042 | H9: =IFERROR(H8/((H4+H7)/2),0) -> 0.042 | I9: =IFERROR(I8/((I4+I7)/2),0) -> 0.042 | J9: =IFERROR(J8/((J4+J7)/2),0) -> 0.042

Sheet PL
A1: THE KRAFT HEINZ COMPANY — PROJECTED INCOME STATEMENT (P&L)
C3: FY2023 | D3: FY2024 | E3: FY2025 | F3: FY2026E | G3: FY2027E | H3: FY2028E | I3: FY2029E | J3: FY2030E
A4: NET SALES | C4: =REVENUE!C12 -> 26640 | D4: =REVENUE!D12 -> 25846 | E4: =REVENUE!E12 -> 24942 | F4: =REVENUE!F12 -> 24438.665 | G4: =REVENUE!G12 -> 24153.163 | H4: =REVENUE!H12 -> 24247.267 | I4: =REVENUE!I12 -> 24534.493 | J4: =REVENUE!J12 -> 24933.092
A5: Cost of Products Sold | C5: =COGS_OPEX!C7 -> 17714 | D5: =COGS_OPEX!D7 -> 16878 | E5: =COGS_OPEX!E7 -> 16633 | F5: =COGS_OPEX!F7 -> 16300.59 | G5: =COGS_OPEX!G7 -> 16061.854 | H5: =COGS_OPEX!H7 -> 16003.196 | I5: =COGS_OPEX!I7 -> 16143.697 | J5: =COGS_OPEX!J7 -> 16331.175
A6: GROSS PROFIT | C6: =C4-C5 -> 8926 | D6: =D4-D5 -> 8968 | E6: =E4-E5 -> 8309 | F6: =F4-F5 -> 8138.0754 | G6: =G4-G5 -> 8091.3097 | H6: =H4-H5 -> 8244.0708 | I6: =I4-I5 -> 8390.7967 | J6: =J4-J5 -> 8601.9168
A7: Gross Margin % | C7: =IFERROR(C6/C4,0) -> 0.33506006 | D7: =IFERROR(D6/D4,0) -> 0.34697826 | E7: =IFERROR(E6/E4,0) -> 0.33313287 | F7: =IFERROR(F6/F4,0) -> 0.333 | G7: =IFERROR(G6/G4,0) -> 0.335 | H7: =IFERROR(H6/H4,0) -> 0.34 | I7: =IFERROR(I6/I4,0) -> 0.342 | J7: =IFERROR(J6/J4,0) -> 0.345
A8: SG&A (excl. impairment) | C8: =COGS_OPEX!C14 -> 3692 | D8: =COGS_OPEX!D14 -> 3616 | E8: =COGS_OPEX!E14 -> 3672 | F8: =COGS_OPEX!F14 -> 3592.4838 | G8: =COGS_OPEX!G14 -> 3502.2087 | H8: =COGS_OPEX!H14 -> 3467.3592 | I8: =COGS_OPEX!I14 -> 3483.898 | J8: =COGS_OPEX!J14 -> 3490.6329
A9: Goodwill Impairment | C9: =COGS_OPEX!C15 -> 510 | D9: =COGS_OPEX!D15 -> 1638 | E9: =COGS_OPEX!E15 -> 6734 | F9: =COGS_OPEX!F15 -> 0 | G9: =COGS_OPEX!G15 -> 0 | H9: =COGS_OPEX!H15 -> 0 | I9: =COGS_OPEX!I15 -> 0 | J9: =COGS_OPEX!J15 -> 0
A10: Intangible Impairment | C10: =COGS_OPEX!C16 -> 152 | D10: =COGS_OPEX!D16 -> 2031 | E10: =COGS_OPEX!E16 -> 2572 | F10: =COGS_OPEX!F16 -> 0 | G10: =COGS_OPEX!G16 -> 0 | H10: =COGS_OPEX!H16 -> 0 | I10: =COGS_OPEX!I16 -> 0 | J10: =COGS_OPEX!J16 -> 0
A11: Total SG&A (incl. impairment) | C11: =C8+C9+C10 -> 4354 | D11: =D8+D9+D10 -> 7285 | E11: =E8+E9+E10 -> 12978 | F11: =F8+F9+F10 -> 3592.4838 | G11: =G8+G9+G10 -> 3502.2087 | H11: =H8+H9+H10 -> 3467.3592 | I11: =I8+I9+I10 -> 3483.898 | J11: =J8+J9+J10 -> 3490.6329
A12: OPERATING INCOME/(LOSS) | C12: =C6-C11 -> 4572 | D12: =D6-D11 -> 1683 | E12: =E6-E11 -> -4669 | F12: =F6-F11 -> 4545.5917 | G12: =G6-G11 -> 4589.101 | H12: =H6-H11 -> 4776.7116 | I12: =I6-I11 -> 4906.8986 | J12: =J6-J11 -> 5111.2839
A13: Operating Margin % | C13: =IFERROR(C12/C4,0) -> 0.17162162 | D13: =IFERROR(D12/D4,0) -> 0.065116459 | E13: =IFERROR(E12/E4,0) -> -0.18719429 | F13: =IFERROR(F12/F4,0) -> 0.186 | G13: =IFERROR(G12/G4,0) -> 0.19 | H13: =IFERROR(H12/H4,0) -> 0.197 | I13: =IFERROR(I12/I4,0) -> 0.2 | J13: =IFERROR(J12/J4,0) -> 0.205
A14: Interest Expense | C14: =DEBT!C8 -> 912 | D14: =DEBT!D8 -> 912 | E14: =DEBT!E8 -> 947 | F14: =DEBT!F8 -> 878.598 | G14: =DEBT!G8 -> 853.398 | H14: =DEBT!H8 -> 828.198 | I14: =DEBT!I8 -> 802.998 | J14: =DEBT!J8 -> 777.798
A15: Other Expense/(Income) | C15: 27 | D15: -85 | E15: -171 | F15: =INPUTS!F94 -> -50 | G15: =INPUTS!G94 -> -50 | H15: =INPUTS!H94 -> -50 | I15: =INPUTS!I94 -> -50 | J15: =INPUTS!J94 -> -50
A16: INCOME/(LOSS) BEFORE TAX | C16: =C12-C14-C15 -> 3633 | D16: =D12-D14-D15 -> 856 | E16: =E12-E14-E15 -> -5445 | F16: =F12-F14-F15 -> 3716.9937 | G16: =G12-G14-G15 -> 3785.703 | H16: =H12-H14-H15 -> 3998.5136 | I16: =I12-I14-I15 -> 4153.9006 | J16: =J12-J14-J15 -> 4383.4859
A17: Tax Provision/(Benefit) | C17: 787 | D17: -1890 | E17: 403 | F17: =F16*INPUTS!F80 -> 780.56867 | G17: =G16*INPUTS!G80 -> 794.99764 | H17: =H16*INPUTS!H80 -> 839.68786 | I17: =I16*INPUTS!I80 -> 872.31914 | J17: =J16*INPUTS!J80 -> 920.53204
A18: Effective Tax Rate % | C18: =IFERROR(C17/C16,0) -> 0.21662538 | D18: =IFERROR(D17/D16,0) -> -2.2079439 | E18: =IFERROR(E17/E16,0) -> -0.074012856 | F18: =IFERROR(F17/F16,0) -> 0.21 | G18: =IFERROR(G17/G16,0) -> 0.21 | H18: =IFERROR(H17/H16,0) -> 0.21 | I18: =IFERROR(I17/I16,0) -> 0.21 | J18: =IFERROR(J17/J16,0) -> 0.21
A19: NET INCOME/(LOSS) | C19: =C16-C17 -> 2846 | D19: =D16-D17 -> 2746 | E19: =E16-E17 -> -5848 | F19: =F16-F17 -> 2936.425 | G19: =G16-G17 -> 2990.7054 | H19: =H16-H17 -> 3158.8258 | I19: =I16-I17 -> 3281.5815 | J19: =J16-J17 -> 3462.9539
A20: Net Margin % | C20: =IFERROR(C19/C4,0) -> 0.10683183 | D20: =IFERROR(D19/D4,0) -> 0.10624468 | E20: =IFERROR(E19/E4,0) -> -0.23446396 | F20: =IFERROR(F19/F4,0) -> 0.12015489 | G20: =IFERROR(G19/G4,0) -> 0.12382251 | H20: =IFERROR(H19/H4,0) -> 0.13027554 | I20: =IFERROR(I19/I4,0) -> 0.13375379 | J20: =IFERROR(J19/J4,0) -> 0.13888987
A21: D&A (memo) | C21: =CAPEX_DA!C11 -> 961 | D21: =CAPEX_DA!D11 -> 948 | E21: =CAPEX_DA!E11 -> 968 | F21: =CAPEX_DA!F11 -> 0 | G21: =CAPEX_DA!G11 -> 0 | H21: =CAPEX_DA!H11 -> 0 | I21: =CAPEX_DA!I11 -> 0 | J21: =CAPEX_DA!J11 -> 0
A22: EBITDA (memo) | C22: =C12+C21 -> 5533 | D22: =D12+D21 -> 2631 | E22: =E12+E21 -> -3701 | F22: =F12+F21 -> 4545.5917 | G22: =G12+G21 -> 4589.101 | H22: =H12+H21 -> 4776.7116 | I22: =I12+I21 -> 4906.8986 | J22: =J12+J21 -> 5111.2839
A23: EBITDA Margin % | C23: =IFERROR(C22/C4,0) -> 0.2076952 | D23: =IFERROR(D22/D4,0) -> 0.10179525 | E23: =IFERROR(E22/E4,0) -> -0.14838425 | F23: =IFERROR(F22/F4,0) -> 0.186 | G23: =IFERROR(G22/G4,0) -> 0.19 | H23: =IFERROR(H22/H4,0) -> 0.197 | I23: =IFERROR(I22/I4,0) -> 0.2 | J23: =IFERROR(J22/J4,0) -> 0.205
A24: EPS (Basic) | C24: =IFERROR(C19/INPUTS!C93,0) -> 0 | D24: =IFERROR(D19/INPUTS!D93,0) -> 0 | E24: =IFERROR(E19/INPUTS!E93,0) -> 0 | F24: =IFERROR(F19/INPUTS!F93,0) -> 2.4800887 | G24: =IFERROR(G19/INPUTS!G93,0) -> 2.5259336 | H24: =IFERROR(H19/INPUTS!H93,0) -> 2.6679272 | I24: =IFERROR(I19/INPUTS!I93,0) -> 2.771606 | J24: =IFERROR(J19/INPUTS!J93,0) -> 2.9247921

Sheet BS
A1: THE KRAFT HEINZ COMPANY — PROJECTED BALANCE SHEET
C3: FY2023 | D3: FY2024 | E3: FY2025 | F3: FY2026E | G3: FY2027E | H3: FY2028E | I3: FY2029E | J3: FY2030E
A4: ASSETS
A5: Cash & Cash Equivalents | C5: 1400 | D5: 1334 | E5: 2615 | F5: =CF!F28 -> 2008.0296 | G5: =CF!G28 -> 1709.4394 | H5: =CF!H28 -> 1556.9816 | I5: =CF!I28 -> 1516.8556 | J5: =CF!J28 -> 1639.6282
A6: Trade Receivables (net) | C6: 2112 | D6: 2147 | E6: 2254 | F6: =NWC!F13 -> 2008.6574 | G6: =NWC!G13 -> 1985.1915 | H6: =NWC!H13 -> 1992.9261 | I6: =NWC!I13 -> 2016.5337 | J6: =NWC!J13 -> 2049.2952
A7: Inventories | C7: 3614 | D7: 3376 | E7: 3167 | F7: =NWC!F14 -> 3081.4813 | G7: =NWC!G14 -> 2992.3453 | H7: =NWC!H14 -> 2937.573 | I7: =NWC!I14 -> 2919.1342 | J7: =NWC!J14 -> 2908.2915
A8: Other Current Assets | C8: 1803 | D8: 1396 | E8: 2091 | F8: =E8 -> 2091 | G8: =F8 -> 2091 | H8: =G8 -> 2091 | I8: =H8 -> 2091 | J8: =I8 -> 2091
A9: TOTAL CURRENT ASSETS | C9: =C5+C6+C7+C8 -> 8929 | D9: =D5+D6+D7+D8 -> 8253 | E9: =E5+E6+E7+E8 -> 10127 | F9: =F5+F6+F7+F8 -> 9189.1683 | G9: =G5+G6+G7+G8 -> 8777.9762 | H9: =H5+H6+H7+H8 -> 8578.4807 | I9: =I5+I6+I7+I8 -> 8543.5235 | J9: =J5+J6+J7+J8 -> 8688.2149
A10: PP&E, net | C10: 7400 | D10: 7152 | E10: 7318 | F10: =CAPEX_DA!F17 -> 8124.4759 | G10: =CAPEX_DA!G17 -> 8969.8367 | H10: =CAPEX_DA!H17 -> 9818.491 | I10: =CAPEX_DA!I17 -> 10677.198 | J10: =CAPEX_DA!J17 -> 11549.857
A11: Goodwill | C11: 29989 | D11: 28673 | E11: 22179 | F11: =E11 -> 22179 | G11: =F11 -> 22179 | H11: =G11 -> 22179 | I11: =H11 -> 22179 | J11: =I11 -> 22179
A12: Intangible Assets, net | C12: 37872 | D12: 39501 | E12: 37529 | F12: =E12-800 -> 36729 | G12: =F12-800 -> 35929 | H12: =G12-800 -> 35129 | I12: =H12-800 -> 34329 | J12: =I12-800 -> 33529
A13: Other Non-Current Assets | C13: 4800 | D13: 4708 | E13: 4633 | F13: =E13 -> 4633 | G13: =F13 -> 4633 | H13: =G13 -> 4633 | I13: =H13 -> 4633 | J13: =I13 -> 4633
A14: TOTAL ASSETS | C14: =C9+C10+C11+C12+C13 -> 88990 | D14: =D9+D10+D11+D12+D13 -> 88287 | E14: =E9+E10+E11+E12+E13 -> 81786 | F14: =F9+F10+F11+F12+F13 -> 80854.644 | G14: =G9+G10+G11+G12+G13 -> 80488.813 | H14: =H9+H10+H11+H12+H13 -> 80337.972 | I14: =I9+I10+I11+I12+I13 -> 80361.722 | J14: =J9+J10+J11+J12+J13 -> 80579.071
A16: LIABILITIES
A17: Accounts Payable | C17: =NWC!C15 -> 4496 | D17: =NWC!D15 -> 4188 | E17: =NWC!E15 -> 4308 | F17: =NWC!F15 -> 4242.6192 | G17: =NWC!G15 -> 4180.4825 | H17: =NWC!H15 -> 4165.2155 | I17: =NWC!I15 -> 4201.784 | J17: =NWC!J15 -> 4250.5799
A18: Current Portion of LT Debt | C18: 652 | D18: 654 | E18: 1908 | F18: =INPUTS!F90 -> 600 | G18: =INPUTS!G90 -> 600 | H18: =INPUTS!H90 -> 600 | I18: =INPUTS!I90 -> 600 | J18: =INPUTS!J90 -> 600
A19: Other Current Liabilities | C19: 2554 | D19: 2411 | E19: 2562 | F19: =E19 -> 2562 | G19: =F19 -> 2562 | H19: =G19 -> 2562 | I19: =H19 -> 2562 | J19: =I19 -> 2562
A20: TOTAL CURRENT LIABILITIES | C20: =C17+C18+C19 -> 7702 | D20: =D17+D18+D19 -> 7253 | E20: =E17+E18+E19 -> 8778 | F20: =F17+F18+F19 -> 7404.6192 | G20: =G17+G18+G19 -> 7342.4825 | H20: =H17+H18+H19 -> 7327.2155 | I20: =I17+I18+I19 -> 7363.784 | J20: =J17+J18+J19 -> 7412.5799
A21: Long-Term Debt | C21: 19900 | D21: 19215 | E21: 19311 | F21: =DEBT!F7-INPUTS!F90 -> 20019 | G21: =DEBT!G7-INPUTS!G90 -> 19419 | H21: =DEBT!H7-INPUTS!H90 -> 18819 | I21: =DEBT!I7-INPUTS!I90 -> 18219 | J21: =DEBT!J7-INPUTS!J90 -> 17619
A22: Other Non-Current Liabilities | C22: 11700 | D22: 12494 | E22: 11908 | F22: =E22 -> 11908 | G22: =F22 -> 11908 | H22: =G22 -> 11908 | I22: =H22 -> 11908 | J22: =I22 -> 11908
A23: TOTAL LIABILITIES | C23: =C20+C21+C22 -> 39302 | D23: =D20+D21+D22 -> 38962 | E23: =E20+E21+E22 -> 39997 | F23: =F20+F21+F22 -> 39331.619 | G23: =G20+G21+G22 -> 38669.482 | H23: =H20+H21+H22 -> 38054.215 | I23: =I20+I21+I22 -> 37490.784 | J23: =J20+J21+J22 -> 36939.58
A25: EQUITY
A26: Common Stock + APIC | C26: 52049 | D26: 52147 | E26: 51299 | F26: =E26 -> 51299 | G26: =F26 -> 51299 | H26: =G26 -> 51299 | I26: =H26 -> 51299 | J26: =I26 -> 51299
A27: Retained Earnings/(Deficit) | C27: 1367 | D27: 2171 | E27: -4629 | F27: =E27+PL!F19-INPUTS!F92*INPUTS!F93 -> -3586.975 | G27: =F27+PL!G19-INPUTS!G92*INPUTS!G93 -> -2490.6696 | H27: =G27+PL!H19-INPUTS!H92*INPUTS!H93 -> -1226.2438 | I27: =H27+PL!I19-INPUTS!I92*INPUTS!I93 -> 160.9377 | J27: =I27+PL!J19-INPUTS!J92*INPUTS!J93 -> 1729.4915
A28: Other Equity Components | C28: -3728 | D28: =D14-D23-D26-D27 -> -4993 | E28: -4881 | F28: =F14-F23-F26-F27 -> -6189 | G28: =G14-G23-G26-G27 -> -6989 | H28: =H14-H23-H26-H27 -> -7789 | I28: =I14-I23-I26-I27 -> -8589 | J28: =J14-J23-J26-J27 -> -9389
A29: TOTAL EQUITY | C29: =C26+C27+C28 -> 49688 | D29: =D26+D27+D28 -> 49325 | E29: =E26+E27+E28 -> 41789 | F29: =F26+F27+F28 -> 41523.025 | G29: =G26+G27+G28 -> 41819.33 | H29: =H26+H27+H28 -> 42283.756 | I29: =I26+I27+I28 -> 42870.938 | J29: =J26+J27+J28 -> 43639.492
A30: TOTAL LIABILITIES & EQUITY | C30: =C23+C29 -> 88990 | D30: =D23+D29 -> 88287 | E30: =E23+E29 -> 81786 | F30: =F23+F29 -> 80854.644 | G30: =G23+G29 -> 80488.813 | H30: =H23+H29 -> 80337.972 | I30: =I23+I29 -> 80361.722 | J30: =J23+J29 -> 80579.071
A31: Balance Check (Assets - L&E = 0) | C31: =C14-C30 -> 0 | D31: =D14-D30 -> 0 | E31: =E14-E30 -> 0 | F31: =F14-F30 -> 0 | G31: =G14-G30 -> 0 | H31: =H14-H30 -> 0 | I31: =I14-I30 -> 0 | J31: =J14-J30 -> 0

Sheet CF
A1: THE KRAFT HEINZ COMPANY — PROJECTED CASH FLOW STATEMENT
C3: FY2023 | D3: FY2024 | E3: FY2025 | F3: FY2026E | G3: FY2027E | H3: FY2028E | I3: FY2029E | J3: FY2030E
A4: OPERATING ACTIVITIES
A5: Net Income/(Loss) | C5: =PL!C19 -> 2846 | D5: =PL!D19 -> 2746 | E5: =PL!E19 -> -5848 | F5: =PL!F19 -> 2936.425 | G5: =PL!G19 -> 2990.7054 | H5: =PL!H19 -> 3158.8258 | I5: =PL!I19 -> 3281.5815 | J5: =PL!J19 -> 3462.9539
A6: + D&A | C6: =PL!C21 -> 961 | D6: =PL!D21 -> 948 | E6: =PL!E21 -> 968 | F6: =PL!F21 -> 0 | G6: =PL!G21 -> 0 | H6: =PL!H21 -> 0 | I6: =PL!I21 -> 0 | J6: =PL!J21 -> 0
A7: + Impairment Losses | C7: =COGS_OPEX!C15+COGS_OPEX!C16 -> 662 | D7: =COGS_OPEX!D15+COGS_OPEX!D16 -> 3669 | E7: =COGS_OPEX!E15+COGS_OPEX!E16 -> 9306 | F7: =COGS_OPEX!F15+COGS_OPEX!F16 -> 0 | G7: =COGS_OPEX!G15+COGS_OPEX!G16 -> 0 | H7: =COGS_OPEX!H15+COGS_OPEX!H16 -> 0 | I7: =COGS_OPEX!I15+COGS_OPEX!I16 -> 0 | J7: =COGS_OPEX!J15+COGS_OPEX!J16 -> 0
A8: + Change in Working Capital | C8: -746 | D8: 491 | E8: 230 | F8: =-NWC!F17 -> 265.48049 | G8: =-NWC!G17 -> 50.465118 | H8: =-NWC!H17 -> 31.770783 | I8: =-NWC!I17 -> 31.399782 | J8: =-NWC!J17 -> 26.876969
A9: + Other Operating Items | C9: 363 | D9: -3670 | E9: -194 | F9: 0 | G9: 0 | H9: 0 | I9: 0 | J9: 0
A10: OPERATING CASH FLOW | C10: =SUM(C5:C9) -> 4086 | D10: =SUM(D5:D9) -> 4184 | E10: =SUM(E5:E9) -> 4462 | F10: =SUM(F5:F9) -> 3201.9055 | G10: =SUM(G5:G9) -> 3041.1705 | H10: =SUM(H5:H9) -> 3190.5965 | I10: =SUM(I5:I9) -> 3312.9813 | J10: =SUM(J5:J9) -> 3489.8308
A12: INVESTING ACTIVITIES
A13: Capital Expenditures | C13: =CAPEX_DA!C7 -> -1013 | D13: =CAPEX_DA!D7 -> -1024 | E13: =CAPEX_DA!E7 -> -801 | F13: =CAPEX_DA!F7 -> -806.47595 | G13: =CAPEX_DA!G7 -> -845.36072 | H13: =CAPEX_DA!H7 -> -848.65435 | I13: =CAPEX_DA!I7 -> -858.70726 | J13: =CAPEX_DA!J7 -> -872.65822
A14: Other Investing Activities | C14: 97 | D14: 133 | E14: -1717 | F14: 0 | G14: 0 | H14: 0 | I14: 0 | J14: 0
A15: INVESTING CASH FLOW | C15: =C13+C14 -> -916 | D15: =D13+D14 -> -891 | E15: =E13+E14 -> -2518 | F15: =F13+F14 -> -806.47595 | G15: =G13+G14 -> -845.36072 | H15: =H13+H14 -> -848.65435 | I15: =I13+I14 -> -858.70726 | J15: =J13+J14 -> -872.65822
A17: FINANCING ACTIVITIES
A18: Debt Repayment | C18: -848 | D18: -618 | E18: -678 | F18: =DEBT!F6 -> -600 | G18: =DEBT!G6 -> -600 | H18: =DEBT!H6 -> -600 | I18: =DEBT!I6 -> -600 | J18: =DEBT!J6 -> -600
A19: New Debt Issuance | C19: 657 | D19: 594 | E19: 1620 | F19: =DEBT!F5 -> 0 | G19: =DEBT!G5 -> 0 | H19: =DEBT!H5 -> 0 | I19: =DEBT!I5 -> 0 | J19: =DEBT!J5 -> 0
A20: Dividends Paid | C20: -1965 | D20: -1931 | E20: -1898 | F20: =-INPUTS!F92*INPUTS!F93 -> -1894.4 | G20: =-INPUTS!G92*INPUTS!G93 -> -1894.4 | H20: =-INPUTS!H92*INPUTS!H93 -> -1894.4 | I20: =-INPUTS!I92*INPUTS!I93 -> -1894.4 | J20: =-INPUTS!J92*INPUTS!J93 -> -1894.4
A21: Share Repurchases | C21: -455 | D21: -988 | E21: -436 | F21: 0 | G21: 0 | H21: 0 | I21: 0 | J21: 0
A22: Other Financing | C22: -67 | D22: -65 | E22: 141 | F22: 0 | G22: 0 | H22: 0 | I22: 0 | J22: 0
A23: FINANCING CASH FLOW | C23: =SUM(C18:C22) -> -2678 | D23: =SUM(D18:D22) -> -3008 | E23: =SUM(E18:E22) -> -1251 | F23: =SUM(F18:F22) -> -2494.4 | G23: =SUM(G18:G22) -> -2494.4 | H23: =SUM(H18:H22) -> -2494.4 | I23: =SUM(I18:I22) -> -2494.4 | J23: =SUM(J18:J22) -> -2494.4
A25: FX Effect on Cash | C25: -19 | D25: -71 | E25: 80 | F25: 0 | G25: 0 | H25: 0 | I25: 0 | J25: 0
A26: NET CHANGE IN CASH | C26: =C10+C15+C23+C25 -> 473 | D26: =D10+D15+D23+D25 -> 214 | E26: =E10+E15+E23+E25 -> 773 | F26: =F10+F15+F23+F25 -> -98.970441 | G26: =G10+G15+G23+G25 -> -298.59019 | H26: =H10+H15+H23+H25 -> -152.4578 | I26: =I10+I15+I23+I25 -> -40.125971 | J26: =J10+J15+J23+J25 -> 122.77259
A27: Beginning Cash Balance | C27: 1041 | D27: 1400 | E27: 1334 | F27: =E28 -> 2107 | G27: =F28 -> 2008.0296 | H27: =G28 -> 1709.4394 | I27: =H28 -> 1556.9816 | J27: =I28 -> 1516.8556
A28: ENDING CASH BALANCE | C28: =C27+C26 -> 1514 | D28: =D27+D26 -> 1614 | E28: =E27+E26 -> 2107 | F28: =F27+F26 -> 2008.0296 | G28: =G27+G26 -> 1709.4394 | H28: =H27+H26 -> 1556.9816 | I28: =I27+I26 -> 1516.8556 | J28: =J27+J26 -> 1639.6282
