Workbook

Sheet COVER
A1: PLANTILLA DE MODELADO FINANCIERO · AIM Analytics
B2: 3-Statement Financial Model · CFI Standard · Escalable y Replicable
A4: INFORMACIÓN DE LA EMPRESA
B5: Empresa / Ticker | C5: Loma Negra Cía. Ind. Argentina S.A. / LOMA (BCBA)
B6: Bolsa / Mercado | C6: BCBA — Bolsas y Mercados Argentinos
B7: Sector | C7: Materiales de Construcción — Cemento, Hormigón, Agregados
B8: Moneda del modelo | C8: ARS — Pesos Argentinos (miles de pesos, IAS 29)
B9: Unidad de reporte | C9: Miles de pesos argentinos (ARS miles)
B10: Fuente de datos | C10: EEFF Consolidados Auditados NIIF — presentados ante CNV
B11: Período fiscal | C11: Diciembre (cierre 31 de diciembre)
B12: Años históricos | C12: FY2023, FY2024, FY2025
B13: Años proyectados | C13: FY2026E – FY2030E
B14: Analista | C14: Gonzalo Dalmasso Müller — AIM Analytics
B15: Fecha del modelo | C15: Junio 2026
A17: COLOR CODING — CFI STANDARD
B18: AZUL + fondo beige | C18: Hardcodes / inputs editables — datos del reporte fuente y supuestos
B19: AZUL | C19: Hardcodes históricos tomados directamente del reporte fuente
B20: NEGRO | C20: Fórmulas y cálculos internos de la misma hoja
B21: VERDE | C21: Links entre hojas (=REVENUE!C5, =PL!E12, etc.)
B22: ROJO | C22: Links a archivos externos
A24: ESTRUCTURA DEL MODELO — 11 HOJAS
B25: COVER | C25: Esta hoja — información de la empresa, color coding e instrucciones
B26: INPUTS | C26: ⭐ HOJA MÁS IMPORTANTE — todos los datos históricos + supuestos de proyección
B27: REVENUE | C27: Buildup de ingresos por segmento. Driver: tasa de crecimiento anual
B28: COGS_OPEX | C28: Buildup de COGS y SGA como % de ventas. Impairments separados
B29: NWC | C29: Net Working Capital — metodología DSO / DIO / DPO
B30: CAPEX_DA | C30: CapEx y D&A como % de ventas. PP&E roll-forward
B31: DEBT | C31: Debt schedule — saldo, emisiones, repagos, intereses sobre saldo promedio
B32: PL | C32: 📊 Income Statement proyectado — P&L completo con márgenes
B33: BS | C33: 📊 Balance Sheet proyectado — con Balance Check (debe = 0)
B34: CF | C34: 📊 Cash Flow Statement proyectado — método indirecto
B35: KPIs | C35: 📈 Ratios y KPIs financieros — rentabilidad, liquidez, apalancamiento, valuación
A37: CÓMO USAR ESTA PLANTILLA — PASO A PASO
B38: PASO 1 | C38: Completar la sección 'Información de la Empresa' arriba con los datos de la empresa a analizar
B39: PASO 2 | C39: Ir a la hoja INPUTS. Cargar todos los datos históricos en celdas AZULES (tomados del reporte fuente)
B40: PASO 3 | C40: En INPUTS sección D, completar los supuestos de proyección en celdas AZULES con fondo AMARILLO
B41: PASO 4 | C41: Las hojas REVENUE, COGS_OPEX, NWC, CAPEX_DA y DEBT se calculan automáticamente
B42: PASO 5 | C42: Verificar que las hojas PL, BS y CF muestren los datos correctos
B43: PASO 6 | C43: Controlar que el Balance Check en la hoja BS sea = 0 en todos los períodos
B44: PASO 7 | C44: Revisar la hoja KPIs para analizar ratios y tendencias
...

Sheet INPUTS
A1: INPUTS — Datos Históricos y Supuestos de Proyección
B2: FY2023A | C2: FY2024A | D2: FY2025A | E2: FY2026E | F2: FY2027E | G2: FY2028E | H2: FY2029E | I2: FY2030E
A3: A. INCOME STATEMENT — Datos Históricos
A4: Net Sales / Ingresos | B4: 919312709 | C4: 919760895 | D4: 848086622
A5: Cost of Goods Sold (COGS) | B5: 688685258 | C5: 673789750 | D5: 663079909
A6: Gross Profit | B6: 230627451 | C6: 245971145 | D6: 185006713
A7: SG&A (excl. impairments) | B7: -84199865 | C7: -96261268 | D7: -94344775
A8: Otros ingresos / egresos netos | B8: 1999220 | C8: 5992358 | D8: 4812823
A9: Impuesto débito/crédito bancario | B9: -10183752 | C9: -9761433 | D9: -9032797
A10: Operating Income / EBIT | B10: =B6+B7+B8+B9 -> 138243054 | C10: 145940802 | D10: 86441964
A11: Diferencias de cambio | B11: -255244812 | C11: -57498049 | D11: -85133230
A12: Resultado por posición monetaria (RECPAM) | B12: 302169399 | C12: 345814744 | D12: 90039231
A13: Ingresos financieros | B13: 12434159 | C13: 2582156 | D13: 3976701
A14: Egresos financieros | B14: -159671181 | C14: -108557350 | D14: -57959601
A15: Income Before Tax (EBT) | B15: =SUM(B10:B14) -> 37930619 | C15: 328282303 | D15: 37365065
A16: Impuesto a las ganancias corriente | B16: -8296615 | C16: -87414437 | D16: -19511734
A17: Impuesto a las ganancias diferido | B17: -8553345 | C17: -38774091 | D17: 4967205
A18: Net Income / (Loss) | B18: =B15+B16+B17 -> 21080659 | C18: 202093775 | D18: 22820536
A20: B. BALANCE SHEET — Datos Históricos
A21: ACTIVO
A22: Inventarios | B22: 166558064 | C22: 265417656 | D22: 294183434
A23: Otros créditos | B23: 47358732 | C23: 18195049 | D23: 37355530
A24: Créditos por ventas (trade receivables) | B24: 49539392 | C24: 64786808 | D24: 76818812
A25: Inversiones corrientes | B25: 3724558 | C25: 760964 | D25: 21654777
A26: Efectivo y equivalentes | B26: 10940003 | C26: 10490878 | D26: 9760886
A27: TOTAL CURRENT ASSETS | B27: 278120749 | C27: 359651355 | D27: 439773439
A29: Propiedad, planta y equipo (PP&E) | B29: 1049899221 | C29: 1386784981 | D29: 1361529149
A30: Activos por derecho de uso | B30: 5545007 | C30: 4178512 | D30: 3241201
A31: Activos intangibles | B31: 3452567 | C31: 3811125 | D31: 8710863
A32: Inversiones en compañías | B32: 69400 | C32: 91295 | D32: 91295
A33: Llave de negocio (Goodwill) | B33: 692222 | C33: 910609 | D33: 910609
A34: Inventarios | B34: 49368121 | C34: 88093611 | D34: 81983557
... A37: TOTAL NO CURRENT ASSETS | B37: 1113051067 | C37: 1492992005 | D37: 1458169773
A38: TOTAL ASSETS | B38: =B37+B27 -> 1391171816 | C38: =C37+C27 -> 1852643360 | D38: =D37+D27 -> 1897943212
A40: PASIVO
A41: Préstamos (financieros) | B41: 81061928 | C41: 132443340 | D41: 134272932
A42: Pasivos por arrendamiento | B42: 2644870 | C42: 1826366 | D42: 2205229
A43: Deudas comerciales (AP) | B43: 124681093 | C43: 123117540 | D43: 118175529
A44: Anticipos de clientes | B44: 9542620 | C44: 8433595 | D44: 14424503
A45: Remuneraciones y cargas sociales | B45: 19324436 | C45: 23560323 | D45: 24360359
...

Sheet REVENUE
A1: REVENUE BUILDUP — Por Segmento
B2: FY2023A | C2: FY2024A | D2: FY2025A | E2: FY2026E | F2: FY2027E | G2: FY2028E | H2: FY2029E | I2: FY2030E | J2: FY20XXE
A3: Segmento 1 Cemento | B3: YoY Growth | C3: 205007364 | D3: 510890006 | E3: =D3*(1+INPUTS!E125) -> 6.2328581e+08 | F3: =E3*(1+INPUTS!F125) -> 7.3547725e+08 | G3: =F3*(1+INPUTS!G125) -> 8.3844407e+08 | H3: =G3*(1+INPUTS!H125) -> 9.2228847e+08 | I3: =H3*(1+INPUTS!I125) -> 9.9607155e+08 | J3: =IFERROR(I3*(1+INPUTS!I125),0) -> 1.0757573e+09
A4: YoY Growth % | C4: N/A | D4: =IFERROR(D3/C3-1,0) -> 1.4920569 | E4: =IFERROR(E3/D3-1,0) -> 0.22 | F4: =IFERROR(F3/E3-1,0) -> 0.18 | G4: =IFERROR(G3/F3-1,0) -> 0.14 | H4: =IFERROR(H3/G3-1,0) -> 0.1 | I4: =IFERROR(I3/H3-1,0) -> 0.08 | J4: =IFERROR(J3/I3-1,0) -> 0.08
A5: Segmento 2 Hormigón | B5: YoY Growth | C5: 21866051 | D5: 45911178 | E5: =D5*(1+INPUTS!E126) -> 56011637 | F5: =E5*(1+INPUTS!F126) -> 66093732 | G5: =F5*(1+INPUTS!G126) -> 75346854 | H5: =G5*(1+INPUTS!H126) -> 82881540 | I5: =H5*(1+INPUTS!I126) -> 89512063 | J5: =IFERROR(I5*(1+INPUTS!I126),0) -> 96673028
A6: YoY Growth % | C6: N/A | D6: =IFERROR(D5/C5-1,0) -> 1.0996557 | E6: =IFERROR(E5/D5-1,0) -> 0.22 | F6: =IFERROR(F5/E5-1,0) -> 0.18 | G6: =IFERROR(G5/F5-1,0) -> 0.14 | H6: =IFERROR(H5/G5-1,0) -> 0.1 | I6: =IFERROR(I5/H5-1,0) -> 0.08 | J6: =IFERROR(J5/I5-1,0) -> 0.08
A7: Segmento 3 Agregados | B7: YoY Growth | C7: 7071371 | D7: 14131733 | E7: =D7*(1+INPUTS!E127) -> 17240714 | F7: =E7*(1+INPUTS!F127) -> 20344043 | G7: =F7*(1+INPUTS!G127) -> 23192209 | H7: =G7*(1+INPUTS!H127) -> 25511430 | I7: =H7*(1+INPUTS!I127) -> 27552344 | J7: =IFERROR(I7*(1+INPUTS!I127),0) -> 29756532
A8: YoY Growth % | C8: N/A | D8: =IFERROR(D7/C7-1,0) -> 0.99844316 | E8: =IFERROR(E7/D7-1,0) -> 0.22 | F8: =IFERROR(F7/E7-1,0) -> 0.18 | G8: =IFERROR(G7/F7-1,0) -> 0.14 | H8: =IFERROR(H7/G7-1,0) -> 0.1 | I8: =IFERROR(I7/H7-1,0) -> 0.08 | J8: =IFERROR(J7/I7-1,0) -> 0.08
A9: Segmento 4 Ferroviario | B9: YoY Growth | C9: 18450706 | D9: 54070555 | E9: =D9*(1+INPUTS!E128) -> 65966077 | F9: =E9*(1+INPUTS!F128) -> 77839971 | G9: =F9*(1+INPUTS!G128) -> 88737567 | H9: =G9*(1+INPUTS!H128) -> 97611324 | I9: =H9*(1+INPUTS!I128) -> 1.0542023e+08 | J9: =IFERROR(I9*(1+INPUTS!I128),0) -> 1.1385385e+08
A10: YoY Growth % | C10: N/A | D10: =IFERROR(D9/C9-1,0) -> 1.9305412 | E10: =IFERROR(E9/D9-1,0) -> 0.22 | F10: =IFERROR(F9/E9-1,0) -> 0.18 | G10: =IFERROR(G9/F9-1,0) -> 0.14 | H10: =IFERROR(H9/G9-1,0) -> 0.1 | I10: =IFERROR(I9/H9-1,0) -> 0.08 | J10: =IFERROR(J9/I9-1,0) -> 0.08
A11: Segmento 5 otros | B11: YoY Growth | C11: =1083067+271908 -> 1354975 | D11: 5872104 | E11: =D11*(1+INPUTS!E129) -> 7163966.9 | F11: =E11*(1+INPUTS!F129) -> 8453480.9 | G11: =F11*(1+INPUTS!G129) -> 9636968.2 | H11: =G11*(1+INPUTS!H129) -> 10600665 | I11: =H11*(1+INPUTS!I129) -> 11448718 | J11: =IFERROR(I11*(1+INPUTS!I129),0) -> 12364616
A12: YoY Growth % | C12: N/A | D12: =IFERROR(D11/C11-1,0) -> 3.333736 | E12: =IFERROR(E11/D11-1,0) -> 0.22 | F12: =IFERROR(F11/E11-1,0) -> 0.18 | G12: =IFERROR(G11/F11-1,0) -> 0.14 | H12: =IFERROR(H11/G11-1,0) -> 0.1 | I12: =IFERROR(I11/H11-1,0) -> 0.08 | J12: =IFERROR(J11/I11-1,0) -> 0.08
A13: TOTAL Segmentos | B13: Suma segmentos | C13: =C3+C5+C7+C9+C11 -> 253750467 | D13: =D3+D5+D7+D9+D11 -> 630875576 | E13: =E3+E5+E7+E9+E11 -> 7.696682e+08 | F13: =F3+F5+F7+F9+F11 -> 9.0820848e+08 | G13: =G3+G5+G7+G9+G11 -> 1.0353577e+09 | H13: =H3+H5+H7+H9+H11 -> 1.1388934e+09 | I13: =I3+I5+I7+I9+I11 -> 1.2300049e+09 | J13: =IFERROR(J3+J5+J7+J9+J11,0) -> 1.3284053e+09
A14: Total YoY Growth % | B14: N/A | C14: =IFERROR(C13/B13-1,0) -> 0 | D14: =IFERROR(D13/C13-1,0) -> 1.4862046 | E14: =IFERROR(E13/D13-1,0) -> 0.22 | F14: =IFERROR(F13/E13-1,0) -> 0.18 | G14: =IFERROR(G13/F13-1,0) -> 0.14 | H14: =IFERROR(H13/G13-1,0) -> 0.1 | I14: =IFERROR(I13/H13-1,0) -> 0.08 | J14: =IFERROR(J13/I13-1,0) -> 0.08
A15: Reconciliación moneda extranjera | C15: =C16-C13 -> 666010428 | D15: =D16-D13 -> 217211046 | E15: 0 | F15: 0 | G15: 0 | H15: 0 | I15: 0
A16: TOTAL Revenue | B16: 919312709 | C16: 919760895 | D16: 848086622 | E16: =E13 -> 7.696682e+08 | F16: =F13 -> 9.0820848e+08 | G16: =G13 -> 1.0353577e+09 | H16: =H13 -> 1.1388934e+09 | I16: =I13 -> 1.2300049e+09

Sheet COGS_OPEX
A1: COGS & OPEX BUILDUP
B2: FY2023A | C2: FY2024A | D2: FY2025A | E2: FY2026E | F2: FY2027E | G2: FY2028E | H2: FY2029E | I2: FY2030E | J2: FY20XXE
A3: Net Sales ($mm) | B3: =REVENUE!B16 -> 919312709 | C3: =REVENUE!C16 -> 919760895 | D3: =REVENUE!D16 -> 848086622 | E3: =REVENUE!E16 -> 7.696682e+08 | F3: =REVENUE!F16 -> 9.0820848e+08 | G3: =REVENUE!G16 -> 1.0353577e+09 | H3: =REVENUE!H16 -> 1.1388934e+09 | I3: =REVENUE!I16 -> 1.2300049e+09 | J3: =IFERROR(REVENUE!J13,0) -> 1.3284053e+09
A5: A. COSTO DE VENTAS (COGS)
A6: COGS como % de ventas | B6: 0.74913057 | C6: 0.73257056 | D6: 0.78185399 | E6: =INPUTS!E131 -> 0.768 | F6: =INPUTS!F131 -> 0.765 | G6: =INPUTS!G131 -> 0.762 | H6: =INPUTS!H131 -> 0.758 | I6: =INPUTS!I131 -> 0.755
A7: Cost of Goods Sold ($mm) | B7: =-B3*B6 -> -6.8868526e+08 | C7: =-C3*C6 -> -6.7378975e+08 | D7: =-D3*D6 -> -6.6307991e+08 | E7: =-E3*E6 -> -5.9110518e+08 | F7: =-F3*F6 -> -6.9477949e+08 | G7: =-G3*G6 -> -7.8894254e+08 | H7: =-H3*H6 -> -8.6328122e+08 | I7: =-I3*I6 -> -9.2865371e+08 | J7: =IFERROR(J3*J6,0) -> 0
A8: GROSS PROFIT ($mm) | B8: =B3+B7 -> 2.3062745e+08 | C8: =C3+C7 -> 2.4597114e+08 | D8: =D3+D7 -> 1.8500671e+08 | E8: =E3+E7 -> 1.7856302e+08 | F8: =F3+F7 -> 2.1342899e+08 | G8: =G3+G7 -> 2.4641512e+08 | H8: =H3+H7 -> 2.7561221e+08 | I8: =I3+I7 -> 3.013512e+08 | J8: =IFERROR(J3-J7,0) -> 1.3284053e+09
A9: Gross Margin % | B9: =IFERROR(B8/B3,0) -> 0.25086943 | C9: =IFERROR(C8/C3,0) -> 0.26742944 | D9: =IFERROR(D8/D3,0) -> 0.21814601 | E9: =IFERROR(E8/E3,0) -> 0.232 | F9: =IFERROR(F8/F3,0) -> 0.235 | G9: =IFERROR(G8/G3,0) -> 0.238 | H9: =IFERROR(H8/H3,0) -> 0.242 | I9: =IFERROR(I8/I3,0) -> 0.245 | J9: =IFERROR(J8/J3,0) -> 1
A11: B. GASTOS OPERATIVOS (SG&A)
A12: SG&A como % de ventas | B12: 0.091590015 | C12: 0.10465901 | D12: 0.11124427 | E12: =INPUTS!E132 -> 0.108 | F12: =INPUTS!F132 -> 0.107 | G12: =INPUTS!G132 -> 0.105 | H12: =INPUTS!H132 -> 0.104 | I12: =INPUTS!I132 -> 0.102
A13: SG&A Expenses ($mm) | B13: =-B3*B12 -> -84199865 | C13: =-C3*C12 -> -96261268 | D13: =-D3*D12 -> -94344775 | E13: =-E3*E12 -> -83124166 | F13: =-F3*F12 -> -97178307 | G13: =-G3*G12 -> -1.0871255e+08 | H13: =-H3*H12 -> -1.1844492e+08 | I13: =-I3*I12 -> -1.254605e+08 | J13: =IFERROR(J3*J12,0) -> 0
A14: Otros ingresos / egresos netos | B14: -8184532 | C14: -3769075 | D14: -4219974 | E14: 0 | F14: 0 | G14: 0 | H14: 0 | I14: 0 | J14: =IFERROR(INPUTS!I133,0) -> 0
A15: Impuesto débito/crédito bancario | B15: 0 | C15: 0 | D15: 0 | E15: 0 | F15: 0 | G15: 0 | H15: 0 | I15: 0 | J15: =IFERROR(INPUTS!I134,0) -> 0
A16: Total SG&A (incl. impairments) | B16: 0 | C16: 0 | D16: 0 | E16: 0 | F16: 0 | G16: 0 | H16: 0 | I16: 0 | J16: =IFERROR(J13+J14+J15,0) -> 0
B17: =B13+B15+B16+B14 -> -92384397 | C17: =C13+C15+C16+C14 -> -1.0003034e+08 | D17: =D13+D15+D16+D14 -> -98564749 | E17: =E13+E15+E16+E14 -> -83124166 | F17: =F13+F15+F16+F14 -> -97178307 | G17: =G13+G15+G16+G14 -> -1.0871255e+08 | H17: =H13+H15+H16+H14 -> -1.1844492e+08 | I17: =I13+I15+I16+I14 -> -1.254605e+08
A18: C. EBITDA SUMMARY
A19: OPERATING INCOME / EBIT ($mm) | C19: =IFERROR(C8+C16,0) -> 2.4597114e+08 | D19: =IFERROR(D8+D16,0) -> 1.8500671e+08 | E19: =IFERROR(E8+E16,0) -> 1.7856302e+08 | F19: =IFERROR(F8+F16,0) -> 2.1342899e+08 | G19: =IFERROR(G8+G16,0) -> 2.4641512e+08 | H19: =IFERROR(H8+H16,0) -> 2.7561221e+08 | I19: =IFERROR(I8+I16,0) -> 3.013512e+08 | J19: =IFERROR(J8+J16,0) -> 1.3284053e+09
A20: Operating Margin % | B20: =B8+B17 -> 1.3824305e+08 | C20: =C8+C17 -> 1.459408e+08 | D20: =D8+D17 -> 86441964 | E20: =E8+E17 -> 95438857 | F20: =F8+F17 -> 1.1625069e+08 | G20: =G8+G17 -> 1.3770257e+08 | H20: =H8+H17 -> 1.5716729e+08 | I20: =I8+I17 -> 1.758907e+08 | J20: =IFERROR(J19/J3,0) -> 1
B21: =IFERROR(B20/B3,0) -> 0.15037653 | C21: =IFERROR(C20/C3,0) -> 0.15867254 | D21: =IFERROR(D20/D3,0) -> 0.10192587 | E21: =IFERROR(E20/E3,0) -> 0.124 | F21: =IFERROR(F20/F3,0) -> 0.128 | G21: =IFERROR(G20/G3,0) -> 0.133 | H21: =IFERROR(H20/H3,0) -> 0.138 | I21: =IFERROR(I20/I3,0) -> 0.143

Sheet NWC
A1: NET WORKING CAPITAL — Metodología DSO / DIO / DPO
A2: DSO = AR/Sales×365 | DIO = Inventory/COGS×365 | DPO = AP/COGS×365 | NWC = AR + Inventory - AP
B3: FY2023A | C3: FY2024A | D3: FY2025A | E3: FY2026E | F3: FY2027E | G3: FY2028E | H3: FY2029E | I3: FY2030E | J3: FY20XXE
A4: Net Sales ($mm) | B4: =REVENUE!B16 -> 919312709 | C4: =REVENUE!C16 -> 919760895 | D4: =REVENUE!D16 -> 848086622 | E4: =REVENUE!E16 -> 7.696682e+08 | F4: =REVENUE!F16 -> 9.0820848e+08 | G4: =REVENUE!G16 -> 1.0353577e+09 | H4: =REVENUE!H16 -> 1.1388934e+09 | I4: =REVENUE!I16 -> 1.2300049e+09 | J4: =IFERROR(REVENUE!J20,0) -> 0
A5: COGS ($mm) | B5: =COGS_OPEX!B7 -> -6.8868526e+08 | C5: =COGS_OPEX!C7 -> -6.7378975e+08 | D5: =COGS_OPEX!D7 -> -6.6307991e+08 | E5: =COGS_OPEX!E7 -> -5.9110518e+08 | F5: =COGS_OPEX!F7 -> -6.9477949e+08 | G5: =COGS_OPEX!G7 -> -7.8894254e+08 | H5: =COGS_OPEX!H7 -> -8.6328122e+08 | I5: =COGS_OPEX!I7 -> -9.2865371e+08 | J5: =IFERROR(COGS_OPEX!J7,0) -> 0
A7: SUPUESTOS DE DÍAS
A8: DSO (días) | B8: 19.668909 | C8: 25.710144 | D8: 33.061324 | E8: =INPUTS!E137 -> 33 | F8: =INPUTS!F137 -> 33 | G8: =INPUTS!G137 -> 32 | H8: =INPUTS!H137 -> 32 | I8: =INPUTS!I137 -> 31 | J8: =IFERROR(INPUTS!I137,0) -> 31
A9: DIO (días) | B9: 88.275003 | C9: 143.77993 | D9: 161.93667 | E9: =INPUTS!E138 -> 158 | F9: =INPUTS!F138 -> 155 | G9: =INPUTS!G138 -> 150 | H9: =INPUTS!H138 -> 145 | I9: =INPUTS!I138 -> 140 | J9: =IFERROR(INPUTS!I138,0) -> 140
A10: DPO (días) | B10: 66.080402 | C10: 66.69425 | D10: 65.051086 | E10: =INPUTS!E139 -> 65 | F10: =INPUTS!F139 -> 65 | G10: =INPUTS!G139 -> 65 | H10: =INPUTS!H139 -> 65 | I10: =INPUTS!I139 -> 65 | J10: =IFERROR(INPUTS!I139,0) -> 65
A12: BALANCE SHEET ITEMS ($mm)
A13: Accounts Receivable | B13: 49539392 | C13: 64786808 | D13: 76818812 | E13: =E8/365*E4 -> 69586440 | F13: =F8/365*F4 -> 82111999 | G13: =G8/365*G4 -> 90771083 | H13: =H8/365*H4 -> 99848191 | I13: =I8/365*I4 -> 1.0446617e+08 | J13: =IFERROR(J8/365*J4,0) -> 0
A14: Inventories | B14: 166558064 | C14: 265417656 | D14: 294183434 | E14: =(E9/365*E5)*-1 -> 2.5587567e+08 | F14: =(F9/365*F5)*-1 -> 2.9504334e+08 | G14: =(G9/365*G5)*-1 -> 3.2422296e+08 | H14: =(H9/365*H5)*-1 -> 3.4294733e+08 | I14: =(I9/365*I5)*-1 -> 3.5619594e+08 | J14: =IFERROR(J9/365*J5,0) -> 0
A15: Accounts Payable | B15: 124681093 | C15: 123117540 | D15: 118175529 | E15: =E10/365*ABS(E5) -> 1.0526531e+08 | F15: =F10/365*ABS(F5) -> 1.2372785e+08 | G15: =G10/365*ABS(G5) -> 1.4049662e+08 | H15: =H10/365*ABS(H5) -> 1.5373501e+08 | I15: =I10/365*ABS(I5) -> 1.6537669e+08 | J15: =IFERROR(J10/365*J5,0) -> 0
A16: NET WORKING CAPITAL (AR + Inv - AP) | B16: =B13+B14-B15 -> 91416363 | C16: =C13+C14-C15 -> 207086924 | D16: =D13+D14-D15 -> 252826717 | E16: =E13+E14-E15 -> 2.201968e+08 | F16: =F13+F14-F15 -> 2.5342749e+08 | G16: =G13+G14-G15 -> 2.7449743e+08 | H16: =H13+H14-H15 -> 2.8906051e+08 | I16: =I13+I14-I15 -> 2.9528542e+08 | J16: =IFERROR(J13+J14-J15,0) -> 0
A17: Variación NWC (aumento = uso de caja) | B17: N/A | C17: =C16-B16 -> 115670561 | D17: =D16-C16 -> 45739793 | E17: =E16-D16 -> -32629916 | F17: =F16-E16 -> 33230688 | G17: =G16-F16 -> 21069939 | H17: =H16-G16 -> 14563086 | I17: =I16-H16 -> 6224910.7 | J17: =IFERROR(J16-I16,0) -> -2.9528542e+08

Sheet CAPEX_DA
A1: CAPEX & D&A — % de Ventas + PP&E Roll-Forward
B2: FY2023A | C2: FY2024A | D2: FY2025A | E2: FY2026E | F2: FY2027E | G2: FY2028E | H2: FY2029E | I2: FY2030E | J2: FY20XXE
A3: Net Sales ($mm) | B3: =REVENUE!B16 -> 919312709 | C3: =REVENUE!C16 -> 919760895 | D3: =REVENUE!D16 -> 848086622 | E3: =REVENUE!E16 -> 7.696682e+08 | F3: =REVENUE!F16 -> 9.0820848e+08 | G3: =REVENUE!G16 -> 1.0353577e+09 | H3: =REVENUE!H16 -> 1.1388934e+09 | I3: =REVENUE!I16 -> 1.2300049e+09 | J3: =IFERROR(REVENUE!J13,0) -> 1.3284053e+09
A5: A. CAPITAL EXPENDITURES
A6: CapEx como % de ventas | B6: 0.086988147 | C6: 0.10545851 | D6: 0.081708223 | E6: =INPUTS!E141 -> 0.088 | F6: =INPUTS!F141 -> 0.085 | G6: =INPUTS!G141 -> 0.082 | H6: =INPUTS!H141 -> 0.08 | I6: =INPUTS!I141 -> 0.078 | J6: =IFERROR(INPUTS!I141,0) -> 0.078
A7: Capital Expenditures ($mm) | B7: -79969309 | C7: -96996613 | D7: -69295651 | E7: =-E3*E6 -> -67730802 | F7: =-F3*F6 -> -77197721 | G7: =-G3*G6 -> -84899329 | H7: =-H3*H6 -> -91111475 | I7: =-I3*I6 -> -95940383 | J7: =IFERROR(-J3*J6,0) -> -1.0361561e+08
A9: B. DEPRECIACIÓN & AMORTIZACIÓN
A10: D&A como % de ventas | B10: 0.076254067 | C10: 0.08957152 | D10: 0.10084776 | E10: =INPUTS!E142 -> 0.1 | F10: =INPUTS!F142 -> 0.1 | G10: =INPUTS!G142 -> 0.098 | H10: =INPUTS!H142 -> 0.095 | I10: =INPUTS!I142 -> 0.093 | J10: =IFERROR(INPUTS!I142,0) -> 0.093
A11: Depreciation & Amortization ($mm) | B11: 70101333 | C11: 82384381 | D11: 85527637 | E11: =E3*E10 -> 76966820 | F11: =F3*F10 -> 90820848 | G11: =G3*G10 -> 1.0146505e+08 | H11: =H3*H10 -> 1.0819488e+08 | I11: =I3*I10 -> 1.1439046e+08 | J11: =IFERROR(J3*J10,0) -> 1.2354169e+08
A13: C. PP&E ROLL-FORWARD
A14: PP&E, net — Opening Balance | B14: 1049899221 | C14: 1049899221 | D14: 1386784981 | E14: =D17 -> 1361529149 | F14: =E17 -> 1.3522931e+09 | G14: =F17 -> 1.33867e+09 | H14: =G17 -> 1.3221043e+09 | I14: =H17 -> 1.3050209e+09 | J14: =IFERROR(I17,0) -> 1.2865708e+09
A15: + Capital Expenditures | B15: =-B7 -> 79969309 | C15: =-C7 -> 96996613 | D15: =-D7 -> 69295651 | E15: =-E7 -> 67730802 | F15: =-F7 -> 77197721 | G15: =-G7 -> 84899329 | H15: =-H7 -> 91111475 | I15: =-I7 -> 95940383 | J15: =IFERROR(-J7,0) -> 1.0361561e+08
A16: - Depreciation & Amortization | B16: =-B11 -> -70101333 | C16: =-C11 -> -82384381 | D16: =-D11 -> -85527637 | E16: =-E11 -> -76966820 | F16: =-F11 -> -90820848 | G16: =-G11 -> -1.0146505e+08 | H16: =-H11 -> -1.0819488e+08 | I16: =-I11 -> -1.1439046e+08 | J16: =IFERROR(-J11,0) -> -1.2354169e+08
A17: PP&E, net — Closing Balance | B17: 1049899221 | C17: 1386784981 | D17: 1361529149 | E17: =E14+E15+E16 -> 1.3522931e+09 | F17: =F14+F15+F16 -> 1.33867e+09 | G17: =G14+G15+G16 -> 1.3221043e+09 | H17: =H14+H15+H16 -> 1.3050209e+09 | I17: =I14+I15+I16 -> 1.2865708e+09 | J17: =IFERROR(I17+J15+J16,0) -> 1.2666447e+09

Sheet DEBT
A1: DEBT SCHEDULE — Saldo, Emisiones, Repagos, Intereses
B2: FY2023A | C2: FY2024A | D2: FY2025A | E2: FY2026E | F2: FY2027E | G2: FY2028E | H2: FY2029E | I2: FY2030E | J2: FY20XXE
A3: DEUDA TOTAL (Corriente + Largo Plazo)
A4: Deuda — Opening Balance ($mm) | B4: N/A | C4: 320918859 | D4: 224818416 | E4: =D7 -> 297908081 | F4: =E7 -> 247908081 | G4: =F7 -> 197908081 | H4: =G7 -> 147908081 | I4: =H7 -> 97908081 | J4: =IFERROR(I7,0) -> 47908081
A5: + Nueva Emisión de Deuda ($mm) | B5: 461562669 | C5: 434282697 | D5: 344451056 | E5: 0 | F5: 0 | G5: 0 | H5: 0 | I5: 0 | J5: =IFERROR(INPUTS!I146,0) -> 0
A6: - Repago de Deuda ($mm) | B6: -241416164 | C6: -413687991 | D6: -283309579 | E6: =INPUTS!E145 -> -50000000 | F6: =INPUTS!F145 -> -50000000 | G6: =INPUTS!G145 -> -50000000 | H6: =INPUTS!H145 -> -50000000 | I6: =INPUTS!I145 -> -50000000 | J6: =IFERROR(-INPUTS!I145,0) -> 50000000
A7: Deuda — Closing Balance ($mm) | B7: 320918859 | C7: 224818416 | D7: 297908081 | E7: =E4+E5+E6 -> 247908081 | F7: =F4+F5+F6 -> 197908081 | G7: =G4+G5+G6 -> 147908081 | H7: =H4+H5+H6 -> 97908081 | I7: =I4+I5+I6 -> 47908081 | J7: =IFERROR(J4+J5+J6,0) -> 97908081
A8: Interest Expense ($mm) | B8: 159671181 | C8: 108557350 | D8: 57959601 | E8: =ABS((E4+E7)/2)*INPUTS!E144 -> 43665293 | F8: =ABS((F4+F7)/2)*INPUTS!F144 -> 30092591 | G8: =ABS((G4+G7)/2)*INPUTS!G144 -> 19019889 | H8: =ABS((H4+H7)/2)*INPUTS!H144 -> 11061727 | I8: =ABS((I4+I7)/2)*INPUTS!I144 -> 5832646.5 | J8: =IFERROR(((J4+J7)/2)*INPUTS!I144,0) -> 5832646.5
A9: Tasa implícita % | B9: N/A | C9: =IFERROR(C8/(ABS(C4+C7)/2),0) -> 0.3978374 | D9: =IFERROR(D8/(ABS(D4+D7)/2),0) -> 0.2217588 | E9: =IFERROR(E8/(ABS(E4+E7)/2),0) -> 0.16 | F9: =IFERROR(F8/(ABS(F4+F7)/2),0) -> 0.135 | G9: =IFERROR(G8/(ABS(G4+G7)/2),0) -> 0.11 | H9: =IFERROR(H8/(ABS(H4+H7)/2),0) -> 0.09 | I9: =IFERROR(I8/(ABS(I4+I7)/2),0) -> 0.08 | J9: =IFERROR(J8/((J4+J7)/2),0) -> 0.08

Sheet PL
A1: PROJECTED INCOME STATEMENT (P&L)
A2: ARS miles | Año fiscal: diciembre | Loma Negra Cía. Ind. Argentina S.A.
B3: FY2023A | C3: FY2024A | D3: FY2025A | E3: FY2026E | F3: FY2027E | G3: FY2028E | H3: FY2029E | I3: FY2030E | J3: FY20XXE
A4: NET SALES / INGRESOS | B4: =REVENUE!B16 -> 919312709 | C4: =REVENUE!C16 -> 919760895 | D4: =REVENUE!D16 -> 848086622 | E4: =REVENUE!E16 -> 7.696682e+08 | F4: =REVENUE!F16 -> 9.0820848e+08 | G4: =REVENUE!G16 -> 1.0353577e+09 | H4: =REVENUE!H16 -> 1.1388934e+09 | I4: =REVENUE!I16 -> 1.2300049e+09 | J4: =IFERROR(REVENUE!J13,0) -> 1.3284053e+09
A5: Cost of Goods Sold (COGS) | B5: =COGS_OPEX!B7 -> -6.8868526e+08 | C5: =COGS_OPEX!C7 -> -6.7378975e+08 | D5: =COGS_OPEX!D7 -> -6.6307991e+08 | E5: =COGS_OPEX!E7 -> -5.9110518e+08 | F5: =COGS_OPEX!F7 -> -6.9477949e+08 | G5: =COGS_OPEX!G7 -> -7.8894254e+08 | H5: =COGS_OPEX!H7 -> -8.6328122e+08 | I5: =COGS_OPEX!I7 -> -9.2865371e+08 | J5: =IFERROR(COGS_OPEX!J7,0) -> 0
A6: GROSS PROFIT | B6: =B4+B5 -> 2.3062745e+08 | C6: =C4+C5 -> 2.4597114e+08 | D6: =D4+D5 -> 1.8500671e+08 | E6: =E4+E5 -> 1.7856302e+08 | F6: =F4+F5 -> 2.1342899e+08 | G6: =G4+G5 -> 2.4641512e+08 | H6: =H4+H5 -> 2.7561221e+08 | I6: =I4+I5 -> 3.013512e+08 | J6: =IFERROR(J4-J5,0) -> 1.3284053e+09
A7: Gross Margin % | B7: =IFERROR(B6/B4,0) -> 0.25086943 | C7: =IFERROR(C6/C4,0) -> 0.26742944 | D7: =IFERROR(D6/D4,0) -> 0.21814601 | E7: =IFERROR(E6/E4,0) -> 0.232 | F7: =IFERROR(F6/F4,0) -> 0.235 | G7: =IFERROR(G6/G4,0) -> 0.238 | H7: =IFERROR(H6/H4,0) -> 0.242 | I7: =IFERROR(I6/I4,0) -> 0.245 | J7: =IFERROR(J6/J4,0) -> 1
A8: SG&A (excl. impairments) | B8: =COGS_OPEX!B13 -> -84199865 | C8: =COGS_OPEX!C13 -> -96261268 | D8: =COGS_OPEX!D13 -> -94344775 | E8: =COGS_OPEX!E13 -> -83124166 | F8: =COGS_OPEX!F13 -> -97178307 | G8: =COGS_OPEX!G13 -> -1.0871255e+08 | H8: =COGS_OPEX!H13 -> -1.1844492e+08 | I8: =COGS_OPEX!I13 -> -1.254605e+08 | J8: =IFERROR(COGS_OPEX!J13,0) -> 0
A9: Goodwill Impairment | B9: 0 | C9: 0 | D9: 0 | E9: 0 | F9: 0 | G9: 0 | H9: 0 | I9: 0 | J9: =IFERROR(COGS_OPEX!J14,0) -> 0
A10: Intangible Impairment | B10: 0 | C10: 0 | D10: 0 | E10: 0 | F10: 0 | G10: 0 | H10: 0 | I10: 0 | J10: =IFERROR(COGS_OPEX!J15,0) -> 0
A11: Total SG&A (incl. impairments) | B11: =COGS_OPEX!B17 -> -92384397 | C11: =COGS_OPEX!C17 -> -1.0003034e+08 | D11: =COGS_OPEX!D17 -> -98564749 | E11: =COGS_OPEX!E17 -> -83124166 | F11: =COGS_OPEX!F17 -> -97178307 | G11: =COGS_OPEX!G17 -> -1.0871255e+08 | H11: =COGS_OPEX!H17 -> -1.1844492e+08 | I11: =COGS_OPEX!I17 -> -1.254605e+08 | J11: =IFERROR(J8+J9+J10,0) -> 0
A12: OPERATING INCOME / EBIT | B12: =COGS_OPEX!B20 -> 1.3824305e+08 | C12: =COGS_OPEX!C20 -> 1.459408e+08 | D12: =COGS_OPEX!D20 -> 86441964 | E12: =COGS_OPEX!E20 -> 95438857 | F12: =COGS_OPEX!F20 -> 1.1625069e+08 | G12: =COGS_OPEX!G20 -> 1.3770257e+08 | H12: =COGS_OPEX!H20 -> 1.5716729e+08 | I12: =COGS_OPEX!I20 -> 1.758907e+08 | J12: =IFERROR(J6-J11,0) -> 1.3284053e+09
A13: Operating Margin % | B13: =IFERROR(B12/B4,0) -> 0.15037653 | C13: =IFERROR(C12/C4,0) -> 0.15867254 | D13: =IFERROR(D12/D4,0) -> 0.10192587 | E13: =IFERROR(E12/E4,0) -> 0.124 | F13: =IFERROR(F12/F4,0) -> 0.128 | G13: =IFERROR(G12/G4,0) -> 0.133 | H13: =IFERROR(H12/H4,0) -> 0.138 | I13: =IFERROR(I12/I4,0) -> 0.143 | J13: =IFERROR(J12/J4,0) -> 1
A14: Interest Expense | B14: =-DEBT!B8 -> -159671181 | C14: =-DEBT!C8 -> -108557350 | D14: =-DEBT!D8 -> -57959601 | E14: =-DEBT!E8 -> -43665293 | F14: =-DEBT!F8 -> -30092591 | G14: =-DEBT!G8 -> -19019889 | H14: =-DEBT!H8 -> -11061727 | I14: =-DEBT!I8 -> -5832646.5 | J14: =IFERROR(DEBT!J8,0) -> 5832646.5
A15: Other Income / (Expense) | B15: -100312435 | C15: 182341501 | D15: -49076899 | E15: =INPUTS!E150 -> -15000000 | F15: =INPUTS!F150 -> -10000000 | G15: =INPUTS!G150 -> -5000000 | H15: =INPUTS!H150 -> -3000000 | I15: =INPUTS!I150 -> -2000000 | J15: =IFERROR(INPUTS!I150,0) -> -2000000
A16: INCOME BEFORE TAX (EBT) | B16: =B12+B14+B15 -> -1.2174056e+08 | C16: =C12+C14+C15 -> 2.1972495e+08 | D16: =D12+D14+D15 -> -20594536 | E16: =E12+E14+E15 -> 36773564 | F16: =F12+F14+F15 -> 76158094 | G16: =G12+G14+G15 -> 1.1368268e+08 | H16: =H12+H14+H15 -> 1.4310557e+08 | I16: =I12+I14+I15 -> 1.6805806e+08 | J16: =IFERROR(J12-J14+J15,0) -> 1.3205727e+09
A17: Tax Provision / (Benefit) | B17: -16849960 | C17: -126188528 | D17: -14544529 | E17: =E16*INPUTS!E135 -> 12870747 | F17: =F16*INPUTS!F135 -> 26655333 | G17: =G16*INPUTS!G135 -> 39788938 | H17: =H16*INPUTS!H135 -> 50086948 | I17: =I16*INPUTS!I135 -> 58820319 | J17: =IFERROR(J16*INPUTS!I135,0) -> 4.6220043e+08
A18: NET INCOME / (LOSS) | B18: 21080659 | C18: 202093775 | D18: 22820536 | E18: =E16-ABS(E17) -> 23902817 | F18: =F16-ABS(F17) -> 49502761 | G18: =G16-ABS(G17) -> 73893742 | H18: =H16-ABS(H17) -> 93018618 | I18: =I16-ABS(I17) -> 1.0923774e+08 | J18: =IFERROR(J16-J17,0) -> 8.5837222e+08
A19: Net Margin % | B19: =IFERROR(B18/B4,0) -> 0.02293089 | C19: =IFERROR(C18/C4,0) -> 0.21972425 | D19: =IFERROR(D18/D4,0) -> 0.026908261 | E19: =IFERROR(E18/E4,0) -> 0.031056001 | F19: =IFERROR(F18/F4,0) -> 0.054505945 | G19: =IFERROR(G18/G4,0) -> 0.071370257 | H19: =IFERROR(H18/H4,0) -> 0.081674558 | I19: =IFERROR(I18/I4,0) -> 0.088810813 | J19: =IFERROR(J18/J4,0) -> 0.64616742
A20: D&A (memo) | B20: =CAPEX_DA!B11 -> 70101333 | C20: =CAPEX_DA!C11 -> 82384381 | D20: =CAPEX_DA!D11 -> 85527637 | E20: =CAPEX_DA!E11 -> 76966820 | F20: =CAPEX_DA!F11 -> 90820848 | G20: =CAPEX_DA!G11 -> 1.0146505e+08 | H20: =CAPEX_DA!H11 -> 1.0819488e+08 | I20: =CAPEX_DA!I11 -> 1.1439046e+08 | J20: =IFERROR(CAPEX_DA!J11,0) -> 1.2354169e+08
A21: EBITDA (memo) | B21: =B12+B20 -> 2.0834439e+08 | C21: =C12+C20 -> 2.2832518e+08 | D21: =D12+D20 -> 1.719696e+08 | E21: =E12+E20 -> 1.7240568e+08 | F21: =F12+F20 -> 2.0707153e+08 | G21: =G12+G20 -> 2.3916762e+08 | H21: =H12+H20 -> 2.6536217e+08 | I21: =I12+I20 -> 2.9028116e+08 | J21: =IFERROR(J12+J20,0) -> 1.451947e+09
A22: EBITDA Margin % | B22: =IFERROR(B21/B4,0) -> 0.2266306 | C22: =IFERROR(C21/C4,0) -> 0.24824406 | D22: =IFERROR(D21/D4,0) -> 0.20277363 | E22: =IFERROR(E21/E4,0) -> 0.224 | F22: =IFERROR(F21/F4,0) -> 0.228 | G22: =IFERROR(G21/G4,0) -> 0.231 | H22: =IFERROR(H21/H4,0) -> 0.233 | I22: =IFERROR(I21/I4,0) -> 0.236 | J22: =IFERROR(J21/J4,0) -> 1.093
A23: EPS (Basic) | B23: =IFERROR(B18/INPUTS!B149,0) -> 0 | C23: =IFERROR(C18/INPUTS!C149,0) -> 0 | D23: =IFERROR(D18/INPUTS!D149,0) -> 0 | E23: =IFERROR(E18/INPUTS!E149,0) -> 40.103648 | F23: =IFERROR(F18/INPUTS!F149,0) -> 83.054701 | G23: =IFERROR(G18/INPUTS!G149,0) -> 123.97738 | H23: =IFERROR(H18/INPUTS!H149,0) -> 156.0647 | I23: =IFERROR(I18/INPUTS!I149,0) -> 183.2768 | J23: =IFERROR(J18/INPUTS!I149,0) -> 1440.159

Sheet BS
A1: PROJECTED BALANCE SHEET
A2: $ en millones | Al cierre del ejercicio fiscal
B3: FY2023A | C3: FY2024A | D3: FY2025A | E3: FY2026E | F3: FY2027E | G3: FY2028E | H3: FY2029E | I3: FY2030E | J3: FY20XXE
A4: ACTIVOS
A5: Cash & Equivalents | B5: 14664561 | C5: 11251842 | D5: 31415663 | E5: =CF!E28 -> 47184414 | F5: =CF!F28 -> 27079614 | G5: =CF!G28 -> 46469140 | H5: =CF!H28 -> 92008074 | I5: =CF!I28 -> 1.6347097e+08 | J5: =IFERROR(CF!J28,0) -> 1.3870547e+09
A6: Accounts Receivable (AR) | B6: =NWC!B13 -> 49539392 | C6: =NWC!C13 -> 64786808 | D6: =NWC!D13 -> 76818812 | E6: =NWC!E13 -> 69586440 | F6: =NWC!F13 -> 82111999 | G6: =NWC!G13 -> 90771083 | H6: =NWC!H13 -> 99848191 | I6: =NWC!I13 -> 1.0446617e+08 | J6: =IFERROR(NWC!J13,0) -> 0
A7: Inventories | B7: =NWC!B14 -> 166558064 | C7: =NWC!C14 -> 265417656 | D7: =NWC!D14 -> 294183434 | E7: =NWC!E14 -> 2.5587567e+08 | F7: =NWC!F14 -> 2.9504334e+08 | G7: =NWC!G14 -> 3.2422296e+08 | H7: =NWC!H14 -> 3.4294733e+08 | I7: =NWC!I14 -> 3.5619594e+08 | J7: =IFERROR(NWC!J14,0) -> 0
A8: Other Current Assets | B8: 51083290 | C8: 18956013 | D8: 59010307 | E8: =D8 -> 59010307 | F8: =E8 -> 59010307 | G8: =F8 -> 59010307 | H8: =G8 -> 59010307 | I8: =H8 -> 59010307 | J8: =IFERROR(I8,0) -> 59010307
A9: TOTAL CURRENT ASSETS | B9: =B5+B6+B7+B8 -> 281845307 | C9: =C5+C6+C7+C8 -> 360412319 | D9: =D5+D6+D7+D8 -> 461428216 | E9: =E5+E6+E7+E8 -> 4.3165683e+08 | F9: =F5+F6+F7+F8 -> 4.6324526e+08 | G9: =G5+G6+G7+G8 -> 5.2047349e+08 | H9: =H5+H6+H7+H8 -> 5.9381391e+08 | I9: =I5+I6+I7+I8 -> 6.8314339e+08 | J9: =IFERROR(J5+J6+J7+J8,0) -> 1.446065e+09
A10: PP&E, net | B10: =CAPEX_DA!B17 -> 1049899221 | C10: =CAPEX_DA!C17 -> 1386784981 | D10: =CAPEX_DA!D17 -> 1361529149 | E10: =CAPEX_DA!E17 -> 1.3522931e+09 | F10: =CAPEX_DA!F17 -> 1.33867e+09 | G10: =CAPEX_DA!G17 -> 1.3221043e+09 | H10: =CAPEX_DA!H17 -> 1.3050209e+09 | I10: =CAPEX_DA!I17 -> 1.2865708e+09 | J10: =IFERROR(CAPEX_DA!J17,0) -> 1.2666447e+09
A11: Goodwill | B11: 692222 | C11: 910609 | D11: 910609 | E11: =D11 -> 910609 | F11: =E11 -> 910609 | G11: =F11 -> 910609 | H11: =G11 -> 910609 | I11: =H11 -> 910609 | J11: =IFERROR(I11,0) -> 910609
A12: Intangible Assets, net | B12: 3452567 | C12: 3811125 | D12: 8710863 | E12: =D12*0.95 -> 8275319.8 | F12: =E12*0.95 -> 7861553.9 | G12: =F12*0.95 -> 7468476.2 | H12: =G12*0.95 -> 7095052.4 | I12: =H12*0.95 -> 6740299.7 | J12: =IFERROR(I12,0) -> 6740299.7
A13: Other Non-Current Assets | B13: 59007057 | C13: 101485290 | D13: 87019152 | E13: =D13 -> 87019152 | F13: =E13 -> 87019152 | G13: =F13 -> 87019152 | H13: =G13 -> 87019152 | I13: =H13 -> 87019152 | J13: =IFERROR(I13,0) -> 87019152
A14: TOTAL ASSETS | B14: =B9+B10+B11+B12+B13 -> 1394896374 | C14: =C9+C10+C11+C12+C13 -> 1853404324 | D14: =D9+D10+D11+D12+D13 -> 1919597989 | E14: =E9+E10+E11+E12+E13 -> 1.880155e+09 | F14: =F9+F10+F11+F12+F13 -> 1.8977066e+09 | G14: =G9+G10+G11+G12+G13 -> 1.937976e+09 | H14: =H9+H10+H11+H12+H13 -> 1.9938596e+09 | I14: =I9+I10+I11+I12+I13 -> 2.0643843e+09 | J14: =IFERROR(J9+J10+J11+J12+J13,0) -> 2.8073798e+09
A16: PASIVOS
A17: Accounts Payable (AP) | B17: =NWC!B15 -> 124681093 | C17: =NWC!C15 -> 123117540 | D17: =NWC!D15 -> 118175529 | E17: =NWC!E15 -> 1.0526531e+08 | F17: =NWC!F15 -> 1.2372785e+08 | G17: =NWC!G15 -> 1.4049662e+08 | H17: =NWC!H15 -> 1.5373501e+08 | I17: =NWC!I15 -> 1.6537669e+08 | J17: =IFERROR(NWC!J15,0) -> 0
A18: Current Portion of LT Debt | B18: 81061928 | C18: 132443340 | D18: 134272932 | E18: =ABS(INPUTS!E145) -> 50000000 | F18: =ABS(INPUTS!F145) -> 50000000 | G18: =ABS(INPUTS!G145) -> 50000000 | H18: =ABS(INPUTS!H145) -> 50000000 | I18: =ABS(INPUTS!I145) -> 50000000 | J18: =IFERROR(INPUTS!I145,0) -> -50000000
A19: Other Current Liabilities | B19: 49823268 | C19: 96754456 | D19: 53653510 | E19: =D19*REVENUE!E16/REVENUE!D16 -> 48692433 | F19: =E19*REVENUE!F16/REVENUE!E16 -> 57457070 | G19: =F19*REVENUE!G16/REVENUE!F16 -> 65501060 | H19: =G19*REVENUE!H16/REVENUE!G16 -> 72051166 | I19: =H19*REVENUE!I16/REVENUE!H16 -> 77815260 | J19: =IFERROR(I19,0) -> 77815260
A20: TOTAL CURRENT LIABILITIES | B20: =B17+B18+B19 -> 255566289 | C20: =C17+C18+C19 -> 352315336 | D20: =D17+D18+D19 -> 306101971 | E20: =E17+E18+E19 -> 2.0395774e+08 | F20: =F17+F18+F19 -> 2.3118492e+08 | G20: =G17+G18+G19 -> 2.5599768e+08 | H20: =H17+H18+H19 -> 2.7578618e+08 | I20: =I17+I18+I19 -> 2.9319195e+08 | J20: =IFERROR(J17+J18+J19,0) -> 27815260
A21: Long-Term Debt | B21: 239856931 | C21: 92375076 | D21: 163635149 | E21: =DEBT!E7-E18 -> 197908081 | F21: =DEBT!F7-F18 -> 147908081 | G21: =DEBT!G7-G18 -> 97908081 | H21: =DEBT!H7-H18 -> 47908081 | I21: =DEBT!I7-I18 -> -2091919 | J21: =IFERROR(DEBT!J7-J18,0) -> 147908081
A22: Other Non-Current Liabilities | B22: 255005111 | C22: 364611126 | D22: 362043734 | E22: =D22 -> 362043734 | F22: =E22 -> 362043734 | G22: =F22 -> 362043734 | H22: =G22 -> 362043734 | I22: =H22 -> 362043734 | J22: =IFERROR(I22,0) -> 362043734
A23: TOTAL LIABILITIES | B23: =B20+B21+B22 -> 750428331 | C23: =C20+C21+C22 -> 809301538 | D23: =D20+D21+D22 -> 831780854 | E23: =E20+E21+E22 -> 7.6390955e+08 | F23: =F20+F21+F22 -> 7.4113674e+08 | G23: =G20+G21+G22 -> 7.1594949e+08 | H23: =H20+H21+H22 -> 6.8573799e+08 | I23: =I20+I21+I22 -> 6.5314376e+08 | J23: =IFERROR(J20+J21+J22,0) -> 5.3776707e+08
A25: PATRIMONIO NETO
A26: Common Stock + APIC | B26: 625773407 | C26: 841299507 | D26: 1043634038 | E26: =D26 -> 1043634038 | F26: =E26 -> 1043634038 | G26: =F26 -> 1043634038 | H26: =G26 -> 1043634038 | I26: =H26 -> 1043634038 | J26: =IFERROR(I26,0) -> 1043634038
A27: Retained Earnings / (Deficit) | B27: 14973197 | C27: 202334531 | D27: 23584613 | E27: =D27+PL!E18-INPUTS!E148*INPUTS!E149 -> 47487430 | F27: =E27+PL!F18-INPUTS!F148*INPUTS!F149 -> 96990191 | G27: =F27+PL!G18-INPUTS!G148*INPUTS!G149 -> 1.7088393e+08 | H27: =G27+PL!H18-INPUTS!H148*INPUTS!H149 -> 2.6390255e+08 | I27: =H27+PL!I18-INPUTS!I148*INPUTS!I149 -> 3.7314029e+08 | J27: =IFERROR(I27+PL!J18-INPUTS!I148*INPUTS!I149,0) -> 1.2315125e+09
A28: Other Equity Components | B28: -39119 | C28: -292216 | D28: -1056293 | E28: =E14-E23-E26-E27 -> 25124018 | F28: =F14-F23-F26-F27 -> 15945614 | G28: =G14-G23-G26-G27 -> 7508546.9 | H28: =H14-H23-H26-H27 -> 585017.11 | I28: =I14-I23-I26-I27 -> -5533828.8 | J28: =IFERROR(J14-J23-J26-J27,0) -> -5533828.8
A29: TOTAL EQUITY / PATRIMONIO NETO | B29: =B26+B27+B28 -> 640707485 | C29: =C26+C27+C28 -> 1043341822 | D29: =D26+D27+D28 -> 1066162358 | E29: =E26+E27+E28 -> 1.1162455e+09 | F29: =F26+F27+F28 -> 1.1565698e+09 | G29: =G26+G27+G28 -> 1.2220265e+09 | H29: =H26+H27+H28 -> 1.3081216e+09 | I29: =I26+I27+I28 -> 1.4112405e+09 | J29: =IFERROR(J26+J27+J28,0) -> 2.2696127e+09
A30: TOTAL LIABILITIES & EQUITY | B30: =B23+B29 -> 1391135816 | C30: =C23+C29 -> 1852643360 | D30: =D23+D29 -> 1897943212 | E30: =E23+E29 -> 1.880155e+09 | F30: =F23+F29 -> 1.8977066e+09 | G30: =G23+G29 -> 1.937976e+09 | H30: =H23+H29 -> 1.9938596e+09 | I30: =I23+I29 -> 2.0643843e+09 | J30: =IFERROR(J23+J29,0) -> 2.8073798e+09
A31: ✓ Balance Check (Assets - L&E = 0) | B31: =B14-B30 -> 3760558 | C31: =C14-C30 -> 760964 | D31: =D14-D30 -> 21654777 | E31: =E14-E30 -> 0 | F31: =F14-F30 -> 0 | G31: =G14-G30 -> 0 | H31: =H14-H30 -> 0 | I31: =I14-I30 -> 0 | J31: =IFERROR(J14-J30,0) -> 0

Sheet CF
A1: PROJECTED CASH FLOW STATEMENT
A2: ARS miles | Método indirecto | Loma Negra S.A.
B3: FY2023A | C3: FY2024A | D3: FY2025A | E3: FY2026E | F3: FY2027E | G3: FY2028E | H3: FY2029E | I3: FY2030E | J3: FY20XXE
A4: ACTIVIDADES OPERATIVAS
A5: Net Income / (Loss) | B5: =PL!B18 -> 21080659 | C5: =PL!C18 -> 202093775 | D5: =PL!D18 -> 22820536 | E5: =PL!E18 -> 23902817 | F5: =PL!F18 -> 49502761 | G5: =PL!G18 -> 73893742 | H5: =PL!H18 -> 93018618 | I5: =PL!I18 -> 1.0923774e+08 | J5: =IFERROR(PL!J18,0) -> 8.5837222e+08
A6: + D&A | B6: =CAPEX_DA!B11 -> 70101333 | C6: =CAPEX_DA!C11 -> 82384381 | D6: =CAPEX_DA!D11 -> 85527637 | E6: =CAPEX_DA!E11 -> 76966820 | F6: =CAPEX_DA!F11 -> 90820848 | G6: =CAPEX_DA!G11 -> 1.0146505e+08 | H6: =CAPEX_DA!H11 -> 1.0819488e+08 | I6: =CAPEX_DA!I11 -> 1.1439046e+08 | J6: =IFERROR(PL!J20,0) -> 1.2354169e+08
A7: + Goodwill + Intangible Impairment | B7: 0 | C7: 0 | D7: 0 | E7: 0 | F7: 0 | G7: 0 | H7: 0 | I7: 0 | J7: =IFERROR(COGS_OPEX!J14+COGS_OPEX!J15,0) -> 0
A8: + Other Non-Cash Items | B8: 93982876 | C8: -120413066 | D8: -42951946 | E8: 0 | F8: 0 | G8: 0 | H8: 0 | I8: 0 | J8: 0
A9: + Change in Working Capital | B9: 0 | C9: 0 | D9: 0 | E9: =-NWC!E17 -> 32629916 | F9: =-NWC!F17 -> -33230688 | G9: =-NWC!G17 -> -21069939 | H9: =-NWC!H17 -> -14563086 | I9: =-NWC!I17 -> -6224910.7 | J9: =IFERROR(-NWC!J17,0) -> 2.9528542e+08
A10: OPERATING CASH FLOW | B10: 185164868 | C10: 164065090 | D10: 65396227 | E10: =SUM(E5:E9) -> 1.3349955e+08 | F10: =SUM(F5:F9) -> 1.0709292e+08 | G10: =SUM(G5:G9) -> 1.5428885e+08 | H10: =SUM(H5:H9) -> 1.8665041e+08 | I10: =SUM(I5:I9) -> 2.1740328e+08 | J10: =SUM(J5:J9) -> 1.2771993e+09
A12: ACTIVIDADES DE INVERSIÓN
A13: Capital Expenditures | B13: =CAPEX_DA!B7 -> -79969309 | C13: =CAPEX_DA!C7 -> -96996613 | D13: =CAPEX_DA!D7 -> -69295651 | E13: =CAPEX_DA!E7 -> -67730802 | F13: =CAPEX_DA!F7 -> -77197721 | G13: =CAPEX_DA!G7 -> -84899329 | H13: =CAPEX_DA!H7 -> -91111475 | I13: =CAPEX_DA!I7 -> -95940383 | J13: =IFERROR(CAPEX_DA!J7,0) -> -1.0361561e+08
A14: Other Investing Activities | B14: 1954704 | C14: 1105576 | D14: 2584271 | E14: 0 | F14: 0 | G14: 0 | H14: 0 | I14: 0 | J14: 0
A15: INVESTING CASH FLOW | B15: -78014605 | C15: -95891037 | D15: -66711380 | E15: =E13+E14 -> -67730802 | F15: =F13+F14 -> -77197721 | G15: =G13+G14 -> -84899329 | H15: =H13+H14 -> -91111475 | I15: =I13+I14 -> -95940383 | J15: =IFERROR(J13+J14,0) -> -1.0361561e+08
A17: ACTIVIDADES DE FINANCIAMIENTO
A18: Debt Repayment | B18: -241416164 | C18: -413687991 | D18: -283309579 | E18: =DEBT!E6 -> -50000000 | F18: =DEBT!F6 -> -50000000 | G18: =DEBT!G6 -> -50000000 | H18: =DEBT!H6 -> -50000000 | I18: =DEBT!I6 -> -50000000 | J18: =IFERROR(DEBT!J6,0) -> 50000000
A19: New Debt Issuance | B19: 461562669 | C19: 434282697 | D19: 344451056 | E19: 0 | F19: 0 | G19: 0 | H19: 0 | I19: 0 | J19: =IFERROR(DEBT!J5,0) -> 0
A20: Dividends Paid | B20: -189116296 | C20: 0 | D20: -2609 | E20: 0 | F20: 0 | G20: 0 | H20: 0 | I20: 0 | J20: =IFERROR(-INPUTS!I148*INPUTS!I149,0) -> 0
A21: Share Repurchases | B21: 0 | C21: 0 | D21: 0 | E21: 0 | F21: 0 | G21: 0 | H21: 0 | I21: 0 | J21: 0
A22: Other Financing | B22: -120499634 | C22: -84087908 | D22: -39740052 | E22: 0 | F22: 0 | G22: 0 | H22: 0 | I22: 0 | J22: 0
A23: FINANCING CASH FLOW | B23: -89469425 | C23: -63493202 | D23: 21398816 | E23: =SUM(E18:E22) -> -50000000 | F23: =SUM(F18:F22) -> -50000000 | G23: =SUM(G18:G22) -> -50000000 | H23: =SUM(H18:H22) -> -50000000 | I23: =SUM(I18:I22) -> -50000000 | J23: =SUM(J18:J22) -> 50000000
A25: FX Effect on Cash | B25: -36318782 | C25: -12720057 | D25: 80158 | E25: 0 | F25: 0 | G25: 0 | H25: 0 | I25: 0 | J25: 0
A26: NET CHANGE IN CASH | B26: =B10+B15+B23+B25 -> -18637944 | C26: =C10+C15+C23+C25 -> -8039206 | D26: =D10+D15+D23+D25 -> 20163821 | E26: =E10+E15+E23+E25 -> 15768751 | F26: =F10+F15+F23+F25 -> -20104800 | G26: =G10+G15+G23+G25 -> 19389526 | H26: =H10+H15+H23+H25 -> 45538934 | I26: =I10+I15+I23+I25 -> 71462899 | J26: =IFERROR(J10+J15+J23+J25,0) -> 1.2235837e+09
A27: Beginning Cash Balance | B27: 33302505 | C27: 19291048 | D27: 11251842 | E27: =D28 -> 31415663 | F27: =E28 -> 47184414 | G27: =F28 -> 27079614 | H27: =G28 -> 46469140 | I27: =H28 -> 92008074 | J27: =IFERROR(I28,0) -> 1.6347097e+08
A28: ENDING CASH BALANCE | B28: 14664561 | C28: 11251842 | D28: 31415663 | E28: =E27+E26 -> 47184414 | F28: =F27+F26 -> 27079614 | G28: =G27+G26 -> 46469140 | H28: =H27+H26 -> 92008074 | I28: =I27+I26 -> 1.6347097e+08 | J28: =IFERROR(J27+J26,0) -> 1.3870547e+09

Sheet KPIs
A1: KPIs & RATIOS FINANCIEROS — Rentabilidad · Liquidez · Apalancamiento · Valuación
A2: Todos los ratios se calculan automáticamente desde PL, BS y CF — Loma Negra S.A.
B3: FY2023A | C3: FY2024A | D3: FY2025A | E3: FY2026E | F3: FY2027E | G3: FY2028E | H3: FY2029E | I3: FY2030E | J3: FY20XXE
A4: RENTABILIDAD
A5: Gross Margin % | B5: =IFERROR(PL!B6/PL!B4,0) -> 0.25086943 | C5: =IFERROR(PL!C6/PL!C4,0) -> 0.26742944 | D5: =IFERROR(PL!D6/PL!D4,0) -> 0.21814601 | E5: =IFERROR(PL!E6/PL!E4,0) -> 0.232 | F5: =IFERROR(PL!F6/PL!F4,0) -> 0.235 | G5: =IFERROR(PL!G6/PL!G4,0) -> 0.238 | H5: =IFERROR(PL!H6/PL!H4,0) -> 0.242 | I5: =IFERROR(PL!I6/PL!I4,0) -> 0.245 | J5: =IFERROR(PL!J6/PL!J4,0) -> 1
A6: EBITDA Margin % | B6: =IFERROR(PL!B21/PL!B4,0) -> 0.2266306 | C6: =IFERROR(PL!C21/PL!C4,0) -> 0.24824406 | D6: =IFERROR(PL!D21/PL!D4,0) -> 0.20277363 | E6: =IFERROR(PL!E21/PL!E4,0) -> 0.224 | F6: =IFERROR(PL!F21/PL!F4,0) -> 0.228 | G6: =IFERROR(PL!G21/PL!G4,0) -> 0.231 | H6: =IFERROR(PL!H21/PL!H4,0) -> 0.233 | I6: =IFERROR(PL!I21/PL!I4,0) -> 0.236 | J6: =IFERROR(PL!J21/PL!J4,0) -> 1.093
A7: Operating Margin % | B7: =IFERROR(PL!B12/PL!B4,0) -> 0.15037653 | C7: =IFERROR(PL!C12/PL!C4,0) -> 0.15867254 | D7: =IFERROR(PL!D12/PL!D4,0) -> 0.10192587 | E7: =IFERROR(PL!E12/PL!E4,0) -> 0.124 | F7: =IFERROR(PL!F12/PL!F4,0) -> 0.128 | G7: =IFERROR(PL!G12/PL!G4,0) -> 0.133 | H7: =IFERROR(PL!H12/PL!H4,0) -> 0.138 | I7: =IFERROR(PL!I12/PL!I4,0) -> 0.143 | J7: =IFERROR(PL!J12/PL!J4,0) -> 1
A8: Net Margin % | B8: =IFERROR(PL!B18/PL!B4,0) -> 0.02293089 | C8: =IFERROR(PL!C18/PL!C4,0) -> 0.21972425 | D8: =IFERROR(PL!D18/PL!D4,0) -> 0.026908261 | E8: =IFERROR(PL!E18/PL!E4,0) -> 0.031056001 | F8: =IFERROR(PL!F18/PL!F4,0) -> 0.054505945 | G8: =IFERROR(PL!G18/PL!G4,0) -> 0.071370257 | H8: =IFERROR(PL!H18/PL!H4,0) -> 0.081674558 | I8: =IFERROR(PL!I18/PL!I4,0) -> 0.088810813 | J8: =IFERROR(PL!J18/PL!J4,0) -> 0.64616742
A9: ROE (NI / Equity) | B9: =IFERROR(PL!B18/BS!B29,0) -> 0.032902158 | C9: =IFERROR(PL!C18/BS!C29,0) -> 0.19369853 | D9: =IFERROR(PL!D18/BS!D29,0) -> 0.021404372 | E9: =IFERROR(PL!E18/BS!E29,0) -> 0.021413584 | F9: =IFERROR(PL!F18/BS!F29,0) -> 0.042801359 | G9: =IFERROR(PL!G18/BS!G29,0) -> 0.060468199 | H9: =IFERROR(PL!H18/BS!H29,0) -> 0.07110854 | I9: =IFERROR(PL!I18/BS!I29,0) -> 0.077405471 | J9: =IFERROR(PL!J18/BS!J29,0) -> 0.37820207
A10: ROA (NI / Assets) | B10: =IFERROR(PL!B18/BS!B14,0) -> 0.015112706 | C10: =IFERROR(PL!C18/BS!C14,0) -> 0.10903923 | D10: =IFERROR(PL!D18/BS!D14,0) -> 0.011888185 | E10: =IFERROR(PL!E18/BS!E14,0) -> 0.012713216 | F10: =IFERROR(PL!F18/BS!F14,0) -> 0.026085572 | G10: =IFERROR(PL!G18/BS!G14,0) -> 0.038129338 | H10: =IFERROR(PL!H18/BS!H14,0) -> 0.046652542 | I10: =IFERROR(PL!I18/BS!I14,0) -> 0.052915408 | J10: =IFERROR(PL!J18/BS!J14,0) -> 0.30575565
A11: ROIC (EBIT(1-t) / IC) | B11: =IFERROR(PL!B12*(1-INPUTS!B135)/(BS!B29+DEBT!B7),0) -> 0.14375964 | C11: =IFERROR(PL!C12*(1-INPUTS!C135)/(BS!C29+DEBT!C7),0) -> 0.11508073 | D11: =IFERROR(PL!D12*(1-INPUTS!D135)/(BS!D29+DEBT!D7),0) -> 0.063370601 | E11: =IFERROR(PL!E12*(1-INPUTS!E135)/(BS!E29+DEBT!E7),0) -> 0.045475274 | F11: =IFERROR(PL!F12*(1-INPUTS!F135)/(BS!F29+DEBT!F7),0) -> 0.055787506 | G11: =IFERROR(PL!G12*(1-INPUTS!G135)/(BS!G29+DEBT!G7),0) -> 0.065336455 | H11: =IFERROR(PL!H12*(1-INPUTS!H135)/(BS!H29+DEBT!H7),0) -> 0.072657599 | I11: =IFERROR(PL!I12*(1-INPUTS!I135)/(BS!I29+DEBT!I7),0) -> 0.078353197 | J11: =IFERROR(PL!J12*(1-INPUTS!I135)/(BS!J29+DEBT!J7),0) -> 0.36471208
A13: LIQUIDEZ
A14: Current Ratio (CA/CL) | B14: =IFERROR(BS!B9/BS!B20,0) -> 1.1028266 | C14: =IFERROR(BS!C9/BS!C20,0) -> 1.0229822 | D14: =IFERROR(BS!D9/BS!D20,0) -> 1.507433 | E14: =IFERROR(BS!E9/BS!E20,0) -> 2.1164033 | F14: =IFERROR(BS!F9/BS!F20,0) -> 2.0037866 | G14: =IFERROR(BS!G9/BS!G20,0) -> 2.033118 | H14: =IFERROR(BS!H9/BS!H20,0) -> 2.1531678 | I14: =IFERROR(BS!I9/BS!I20,0) -> 2.330021 | J14: =IFERROR(BS!J9/BS!J20,0) -> 51.98819
A15: Quick Ratio ((CA-Inv)/CL) | B15: =IFERROR((BS!B9-BS!B7)/BS!B20,0) -> 0.45110505 | C15: =IFERROR((BS!C9-BS!C7)/BS!C20,0) -> 0.26962966 | D15: =IFERROR((BS!D9-BS!D7)/BS!D20,0) -> 0.5463695 | E15: =IFERROR((BS!E9-BS!E7)/BS!E20,0) -> 0.8618509 | F15: =IFERROR((BS!F9-BS!F7)/BS!F20,0) -> 0.7275644 | G15: =IFERROR((BS!G9-BS!G7)/BS!G20,0) -> 0.76661059 | H15: =IFERROR((BS!H9-BS!H7)/BS!H20,0) -> 0.90964157 | I15: =IFERROR((BS!I9-BS!I7)/BS!I20,0) -> 1.1151311 | J15: =IFERROR((BS!J9-BS!J7)/BS!J20,0) -> 51.98819
A16: Cash Ratio (Cash/CL) | B16: =IFERROR(BS!B5/BS!B20,0) -> 0.057380655 | C16: =IFERROR(BS!C5/BS!C20,0) -> 0.03193685 | D16: =IFERROR(BS!D5/BS!D20,0) -> 0.10263136 | E16: =IFERROR(BS!E5/BS!E20,0) -> 0.23134407 | F16: =IFERROR(BS!F5/BS!F20,0) -> 0.117134 | G16: =IFERROR(BS!G5/BS!G20,0) -> 0.18152173 | H16: =IFERROR(BS!H5/BS!H20,0) -> 0.33362105 | I16: =IFERROR(BS!I5/BS!I20,0) -> 0.55755615 | J16: =IFERROR(BS!J5/BS!J20,0) -> 49.866682
A17: Operating CF / CL | B17: =IFERROR(CF!B10/BS!B20,0) -> 0.72452775 | C17: =IFERROR(CF!C10/BS!C20,0) -> 0.46567683 | D17: =IFERROR(CF!D10/BS!D20,0) -> 0.21364197 | E17: =IFERROR(CF!E10/BS!E20,0) -> 0.65454517 | F17: =IFERROR(CF!F10/BS!F20,0) -> 0.46323488 | G17: =IFERROR(CF!G10/BS!G20,0) -> 0.60269631 | H17: =IFERROR(CF!H10/BS!H20,0) -> 0.67679392 | I17: =IFERROR(CF!I10/BS!I20,0) -> 0.74150496 | J17: =IFERROR(CF!J10/BS!J20,0) -> 45.917218
A19: EFICIENCIA
A20: DSO (días) | B20: =IFERROR(BS!B6/PL!B4*365,0) -> 19.668909 | C20: =IFERROR(BS!C6/PL!C4*365,0) -> 25.710144 | D20: =IFERROR(BS!D6/PL!D4*365,0) -> 33.061324 | E20: =IFERROR(BS!E6/PL!E4*365,0) -> 33 | F20: =IFERROR(BS!F6/PL!F4*365,0) -> 33 | G20: =IFERROR(BS!G6/PL!G4*365,0) -> 32 | H20: =IFERROR(BS!H6/PL!H4*365,0) -> 32 | I20: =IFERROR(BS!I6/PL!I4*365,0) -> 31 | J20: =IFERROR(BS!J6/PL!J4*365,0) -> 0
A21: DIO (días) | B21: =IFERROR(BS!B7/ABS(PL!B5)*365,0) -> 88.275003 | C21: =IFERROR(BS!C7/ABS(PL!C5)*365,0) -> 143.77993 | D21: =IFERROR(BS!D7/ABS(PL!D5)*365,0) -> 161.93667 | E21: =IFERROR(BS!E7/ABS(PL!E5)*365,0) -> 158 | F21: =IFERROR(BS!F7/ABS(PL!F5)*365,0) -> 155 | G21: =IFERROR(BS!G7/ABS(PL!G5)*365,0) -> 150 | H21: =IFERROR(BS!H7/ABS(PL!H5)*365,0) -> 145 | I21: =IFERROR(BS!I7/ABS(PL!I5)*365,0) -> 140 | J21: =IFERROR(BS!J7/PL!J5*365,0) -> 0
A22: DPO (días) | B22: =IFERROR(BS!B17/ABS(PL!B5)*365,0) -> 66.080402 | C22: =IFERROR(BS!C17/ABS(PL!C5)*365,0) -> 66.69425 | D22: =IFERROR(BS!D17/ABS(PL!D5)*365,0) -> 65.051086 | E22: =IFERROR(BS!E17/ABS(PL!E5)*365,0) -> 65 | F22: =IFERROR(BS!F17/ABS(PL!F5)*365,0) -> 65 | G22: =IFERROR(BS!G17/ABS(PL!G5)*365,0) -> 65 | H22: =IFERROR(BS!H17/ABS(PL!H5)*365,0) -> 65 | I22: =IFERROR(BS!I17/ABS(PL!I5)*365,0) -> 65 | J22: =IFERROR(BS!J17/PL!J5*365,0) -> 0
A23: Asset Turnover (Sales/Assets) | B23: =IFERROR(PL!B4/BS!B14,0) -> 0.65905448 | C23: =IFERROR(PL!C4/BS!C14,0) -> 0.49625486 | D23: =IFERROR(PL!D4/BS!D14,0) -> 0.44180429 | E23: =IFERROR(PL!E4/BS!E14,0) -> 0.40936422 | F23: =IFERROR(PL!F4/BS!F14,0) -> 0.47858214 | G23: =IFERROR(PL!G4/BS!G14,0) -> 0.53424689 | H23: =IFERROR(PL!H4/BS!H14,0) -> 0.57120042 | I23: =IFERROR(PL!I4/BS!I14,0) -> 0.59582169 | J23: =IFERROR(PL!J4/BS!J14,0) -> 0.47318332
A25: APALANCAMIENTO
A26: Deuda Neta ($mm) | B26: =DEBT!B7-BS!B5 -> 306254298 | C26: =DEBT!C7-BS!C5 -> 213566574 | D26: =DEBT!D7-BS!D5 -> 266492418 | E26: =DEBT!E7-BS!E5 -> 2.0072367e+08 | F26: =DEBT!F7-BS!F5 -> 1.7082847e+08 | G26: =DEBT!G7-BS!G5 -> 1.0143894e+08 | H26: =DEBT!H7-BS!H5 -> 5900006.5 | I26: =DEBT!I7-BS!I5 -> -1.1556289e+08 | J26: =IFERROR(DEBT!J7-BS!J5,0) -> -1.2891466e+09
A27: Deuda Neta / EBITDA | B27: =IFERROR((DEBT!B7-BS!B5)/PL!B21,0) -> 1.4699426 | C27: =IFERROR((DEBT!C7-BS!C5)/PL!C21,0) -> 0.93536145 | D27: =IFERROR((DEBT!D7-BS!D5)/PL!D21,0) -> 1.5496484 | E27: =IFERROR((DEBT!E7-BS!E5)/PL!E21,0) -> 1.1642521 | F27: =IFERROR((DEBT!F7-BS!F5)/PL!F21,0) -> 0.82497321 | G27: =IFERROR((DEBT!G7-BS!G5)/PL!G21,0) -> 0.42413325 | H27: =IFERROR((DEBT!H7-BS!H5)/PL!H21,0) -> 0.022233789 | I27: =IFERROR((DEBT!I7-BS!I5)/PL!I21,0) -> -0.39810676 | J27: =IFERROR((DEBT!J7-BS!J5)/PL!J21,0) -> -0.88787444
A28: Deuda Total / Equity | B28: =IFERROR(DEBT!B7/BS!B29,0) -> 0.50088202 | C28: =IFERROR(DEBT!C7/BS!C29,0) -> 0.21547916 | D28: =IFERROR(DEBT!D7/BS!D29,0) -> 0.27942093 | E28: =IFERROR(DEBT!E7/BS!E29,0) -> 0.222091 | F28: =IFERROR(DEBT!F7/BS!F29,0) -> 0.17111641 | G28: =IFERROR(DEBT!G7/BS!G29,0) -> 0.12103508 | H28: =IFERROR(DEBT!H7/BS!H29,0) -> 0.074846314 | I28: =IFERROR(DEBT!I7/BS!I29,0) -> 0.033947496 | J28: =IFERROR(DEBT!J7/BS!J29,0) -> 0.043138673
A29: Deuda Total / Assets | B29: =IFERROR(DEBT!B7/BS!B14,0) -> 0.23006645 | C29: =IFERROR(DEBT!C7/BS!C14,0) -> 0.12130025 | D29: =IFERROR(DEBT!D7/BS!D14,0) -> 0.15519295 | E29: =IFERROR(DEBT!E7/BS!E14,0) -> 0.13185513 | F29: =IFERROR(DEBT!F7/BS!F14,0) -> 0.10428803 | G29: =IFERROR(DEBT!G7/BS!G14,0) -> 0.076320904 | H29: =IFERROR(DEBT!H7/BS!H14,0) -> 0.049104802 | I29: =IFERROR(DEBT!I7/BS!I14,0) -> 0.023206959 | J29: =IFERROR(DEBT!J7/BS!J14,0) -> 0.034875253
A30: Interest Coverage (EBIT/IntExp) | B30: =IFERROR(PL!B12/DEBT!B8,0) -> 0.86579841 | C30: =IFERROR(PL!C12/DEBT!C8,0) -> 1.3443659 | D30: =IFERROR(PL!D12/DEBT!D8,0) -> 1.4914175 | E30: =IFERROR(PL!E12/DEBT!E8,0) -> 2.1856914 | F30: =IFERROR(PL!F12/DEBT!F8,0) -> 3.8630999 | G30: =IFERROR(PL!G12/DEBT!G8,0) -> 7.239925 | H30: =IFERROR(PL!H12/DEBT!H8,0) -> 14.208205 | I30: =IFERROR(PL!I12/DEBT!I8,0) -> 30.156243 | J30: =IFERROR(PL!J12/PL!J14,0) -> 227.75344
A31: FCF ($mm) | B31: =CF!B10+CF!B13 -> 105195559 | C31: =CF!C10+CF!C13 -> 67068477 | D31: =CF!D10+CF!D13 -> -3899424 | E31: =CF!E10+CF!E13 -> 65768751 | F31: =CF!F10+CF!F13 -> 29895200 | G31: =CF!G10+CF!G13 -> 69389526 | H31: =CF!H10+CF!H13 -> 95538934 | I31: =CF!I10+CF!I13 -> 1.214629e+08 | J31: =IFERROR(CF!J10+CF!J13,0) -> 1.1735837e+09
A32: FCF Yield (FCF/EBITDA) | B32: =IFERROR((CF!B10+CF!B13)/PL!B21,0) -> 0.50491189 | C32: =IFERROR((CF!C10+CF!C13)/PL!C21,0) -> 0.29374104 | D32: =IFERROR((CF!D10+CF!D13)/PL!D21,0) -> -0.022675077 | E32: =IFERROR((CF!E10+CF!E13)/PL!E21,0) -> 0.38147671 | F32: =IFERROR((CF!F10+CF!F13)/PL!F21,0) -> 0.14437137 | G32: =IFERROR((CF!G10+CF!G13)/PL!G21,0) -> 0.29012926 | H32: =IFERROR((CF!H10+CF!H13)/PL!H21,0) -> 0.36003223 | I32: =IFERROR((CF!I10+CF!I13)/PL!I21,0) -> 0.41843191 | J32: =IFERROR((CF!J10+CF!J13)/PL!J21,0) -> 0.80828276
A34: CRECIMIENTO
A35: Revenue Growth % | B35: =IFERROR(PL!B4/PL!B4-1,"N/A") -> 0 | C35: =IFERROR(PL!C4/PL!B4-1,"N/A") -> 0.0004875229 | D35: =IFERROR(PL!D4/PL!C4-1,"N/A") -> -0.077927071 | E35: =IFERROR(PL!E4/PL!D4-1,"N/A") -> -0.092465106 | F35: =IFERROR(PL!F4/PL!E4-1,"N/A") -> 0.18 | G35: =IFERROR(PL!G4/PL!F4-1,"N/A") -> 0.14 | H35: =IFERROR(PL!H4/PL!G4-1,"N/A") -> 0.1 | I35: =IFERROR(PL!I4/PL!H4-1,"N/A") -> 0.08 | J35: =IFERROR(PL!J4/PL!I4-1,"N/A") -> 0.08
A36: EBITDA Growth % | B36: =IFERROR(PL!B21/PL!B21-1,"N/A") -> 0 | C36: =IFERROR(PL!C21/PL!B21-1,"N/A") -> 0.095902732 | D36: =IFERROR(PL!D21/PL!C21-1,"N/A") -> -0.24682158 | E36: =IFERROR(PL!E21/PL!D21-1,"N/A") -> 0.0025357761 | F36: =IFERROR(PL!F21/PL!E21-1,"N/A") -> 0.20107143 | G36: =IFERROR(PL!G21/PL!F21-1,"N/A") -> 0.155 | H36: =IFERROR(PL!H21/PL!G21-1,"N/A") -> 0.10952381 | I36: =IFERROR(PL!I21/PL!H21-1,"N/A") -> 0.093905579 | J36: =IFERROR(PL!J21/PL!I21-1,"N/A") -> 4.0018644
A37: Net Income Growth % | B37: =IFERROR(PL!B18/PL!B18-1,"N/A") -> 0 | C37: =IFERROR(PL!C18/PL!B18-1,"N/A") -> 8.5866915 | D37: =IFERROR(PL!D18/PL!C18-1,"N/A") -> -0.88707947 | E37: =IFERROR(PL!E18/PL!D18-1,"N/A") -> 0.047425736 | F37: =IFERROR(PL!F18/PL!E18-1,"N/A") -> 1.0710012 | G37: =IFERROR(PL!G18/PL!F18-1,"N/A") -> 0.49271961 | H37: =IFERROR(PL!H18/PL!G18-1,"N/A") -> 0.2588159 | I37: =IFERROR(PL!I18/PL!H18-1,"N/A") -> 0.17436421 | J37: =IFERROR(PL!J18/PL!I18-1,"N/A") -> 6.8578361
A38: CapEx / Revenue % | B38: =IFERROR(-CAPEX_DA!B7/PL!B4,0) -> 0.086988147 | C38: =IFERROR(-CAPEX_DA!C7/PL!C4,0) -> 0.10545851 | D38: =IFERROR(-CAPEX_DA!D7/PL!D4,0) -> 0.081708223 | E38: =IFERROR(-CAPEX_DA!E7/PL!E4,0) -> 0.088 | F38: =IFERROR(-CAPEX_DA!F7/PL!F4,0) -> 0.085 | G38: =IFERROR(-CAPEX_DA!G7/PL!G4,0) -> 0.082 | H38: =IFERROR(-CAPEX_DA!H7/PL!H4,0) -> 0.08 | I38: =IFERROR(-CAPEX_DA!I7/PL!I4,0) -> 0.078 | J38: =IFERROR(-CAPEX_DA!J7/PL!J4,0) -> 0.078
A39: Revenue ($mm) | B39: =PL!B4 -> 919312709 | C39: =PL!C4 -> 919760895 | D39: =PL!D4 -> 848086622 | E39: =PL!E4 -> 7.696682e+08 | F39: =PL!F4 -> 9.0820848e+08 | G39: =PL!G4 -> 1.0353577e+09 | H39: =PL!H4 -> 1.1388934e+09 | I39: =PL!I4 -> 1.2300049e+09 | J39: =IFERROR(PL!J4,0) -> 1.3284053e+09
A40: EBITDA ($mm) | B40: =PL!B21 -> 2.0834439e+08 | C40: =PL!C21 -> 2.2832518e+08 | D40: =PL!D21 -> 1.719696e+08 | E40: =PL!E21 -> 1.7240568e+08 | F40: =PL!F21 -> 2.0707153e+08 | G40: =PL!G21 -> 2.3916762e+08 | H40: =PL!H21 -> 2.6536217e+08 | I40: =PL!I21 -> 2.9028116e+08 | J40: =IFERROR(PL!J21,0) -> 1.451947e+09
A41: Net Income ($mm) | B41: =PL!B18 -> 21080659 | C41: =PL!C18 -> 202093775 | D41: =PL!D18 -> 22820536 | E41: =PL!E18 -> 23902817 | F41: =PL!F18 -> 49502761 | G41: =PL!G18 -> 73893742 | H41: =PL!H18 -> 93018618 | I41: =PL!I18 -> 1.0923774e+08 | J41: =IFERROR(PL!J18,0) -> 8.5837222e+08
A42: EPS | B42: =PL!B23 -> 0 | C42: =PL!C23 -> 0 | D42: =PL!D23 -> 0 | E42: =PL!E23 -> 40.103648 | F42: =PL!F23 -> 83.054701 | G42: =PL!G23 -> 123.97738 | H42: =PL!H23 -> 156.0647 | I42: =PL!I23 -> 183.2768 | J42: =IFERROR(PL!J23,0) -> 1440.159
A44: VALUACIÓN — completar precio de mercado
A45: Precio de mercado (manual) | C45: [N/A] | D45: [N/A] | E45: [N/A] | F45: [N/A] | G45: [N/A] | H45: [N/A] | I45: [N/A] | J45: [N/A]
...
